Workbook

Sheet ①名簿入力
A1: ① 名簿入力 | D1: 4行目から名簿を貼り付け（白い欄＝入力／灰色＝自動計算）。〇・性別・分けたい人はリストから選べます。U列に「自動案」が出ます → ②へ
A2: 番号 | B2: 旧 クラス | C2: 氏名 | D2: ふりがな | E2: 性別 | F2: 国語 | G2: 数学 | H2: 英語 | I2: 理科 | J2: 社会 | K2: 5教科 平均 | L2: 50m走 (秒) | M2: ピアノ | N2: ムード メーカー | O2: 注意 | P2: 休み がち | Q2: 分けたい人① | R2: 分けたい人② | S2: 分けたい人③ | T2: 備考 | U2: 自動案 (組) | V2: 決定 (②の組) | W2: 選択肢 | X2: 性別ｺｰﾄﾞ | Y2: ピアノ01 | Z2: ムード01 | AA2: 注意01 | AB2: 休み01 | AC2: 区分 | AD2: 平均(補完) | AE2: 並びキー | AF2: 並び順 | AG2: 分けたいID① | AH2: 分けたいID② | AI2: 分けたいID③ | AJ2: 旧クラス番号 | AK2: 50m二乗 | AL2: 50m z
A3: 2101 | B3: 1 | C3: 佐賀 太郎 | D3: さが たろう | E3: 男 | F3: 72 | G3: 65 | H3: 80 | I3: 58 | J3: 70 | K3: (自動) | L3: 7.8 | M3: 〇 | N3: 〇 | Q3: 2105 山田 花子 | T3: ← 記入例（この行は計算に入りません） | U3: (自動) | V3: (自動)
A4: 2101 | B4: 1 | C4: 青木 花音 | D4: あおき かのん | E4: 女 | F4: 48 | G4: 52 | H4: 57 | I4: 60 | J4: 58 | K4: =IF(COUNT(F4:J4)=0,"",ROUND(AVERAGE(F4:J4),1)) -> 55 | L4: 8.9 | M4: × | U4: =IF(A4="","",INDEX('計算'!$Z$2:$Z$151,AF4)) -> 1 | V4: =IF(A4="","",IFERROR(IF(INDEX('②クラス編成'!$E$9:$E$158,MATCH(A4,'②クラス編成'!$D$9:$D$158,0))="","未",INDEX('②クラス編成'!$E$9:$E$158,MATCH(A4,'②クラス編成'!$D$9:$D$158,0))),"未")) -> 1 | W4: =IF(A4="","",A4&" "&C4) -> 2101 青木 花音 | X4: =IF(A4="","",IF(E4="男",1,IF(E4="女",2,3))) -> 2 | Y4: =IF(OR(M4="〇",M4="○",M4="◯"),1,0) -> 0 | Z4: =IF(OR(N4="〇",N4="○",N4="◯"),1,0) -> 0 | AA4: =IF(OR(O4="〇",O4="○",O4="◯"),1,0) -> 0 | AB4: =IF(OR(P4="〇",P4="○",P4="◯"),1,0) -> 0 | AC4: =IF(A4="","",IF(AA4=1,1,IF(Y4=1,2,IF(Z4=1,3,IF(AB4=1,4,5))))) -> 5 | AD4: =IF(A4="","",IF(K4="",'設定'!$C$37,K4)) -> 55 | AE4: =IF(A4="","",AC4*10000000-ROUND(ABS((AD4-'設定'!$C$37)/'設定'!$C$38)*10000,0)) -> 49994408 | AF4: =IF(A4="","",COUNTIF($AE$4:$AE$153,"<"&AE4)+COUNTIFS($AE$4:$AE$153,AE4,$A$4:$A$153,"<"&A4)+1) -> 79 | AG4: =IF(Q4="","",IFERROR(VALUE(LEFT(Q4,FIND(" ",Q4&" ")-1)),IFERROR(INDEX($A$4:$A$153,MATCH(Q4,$C$4:$C$153,0)),""))) | AH4: =IF(R4="","",IFERROR(VALUE(LEFT(R4,FIND(" ",R4&" ")-1)),IFERROR(INDEX($A$4:$A$153,MATCH(R4,$C$4:$C$153,0)),""))) | AI4: =IF(S4="","",IFERROR(VALUE(LEFT(S4,FIND(" ",S4&" ")-1)),IFERROR(INDEX($A$4:$A$153,MATCH(S4,$C$4:$C$153,0)),""))) | AJ4: =IF(OR(A4="",B4=""),"",IF(COUNTIFS($B$4:B4,B4,$A$4:A4,"<>")=1,MAX($AJ$3:AJ3)+1,"")) -> 1 | AK4: =IF(OR(A4="",NOT(ISNUMBER(L4))),"",L4^2) -> 79.21 | AL4: =IF(OR(A4="",NOT(ISNUMBER(L4))),0,(L4-INDEX('計算'!$AE$7:$AG$7,X4))/INDEX('計算'!$AE$8:$AG$8,X4)) -> 0.057799284
A5: 2102 | B5: 1 | C5: 阿部 陽葵 | D5: あべ ひまり | E5: 女 | F5: 35 | G5: 43 | H5: 28 | I5: 34 | J5: 34 | K5: =IF(COUNT(F5:J5)=0,"",ROUND(AVERAGE(F5:J5),1)) -> 34.8 | L5: 8.8 | M5: × | U5: =IF(A5="","",INDEX('計算'!$Z$2:$Z$151,AF5)) -> 3 | V5: =IF(A5="","",IFERROR(IF(INDEX('②クラス編成'!$E$9:$E$158,MATCH(A5,'②クラス編成'!$D$9:$D$158,0))="","未",INDEX('②クラス編成'!$E$9:$E$158,MATCH(A5,'②クラス編成'!$D$9:$D$158,0))),"未")) -> 3 | W5: =IF(A5="","",A5&" "&C5) -> 2102 阿部 陽葵 | X5: =IF(A5="","",IF(E5="男",1,IF(E5="女",2,3))) -> 2 | Y5: =IF(OR(M5="〇",M5="○",M5="◯"),1,0) -> 0 | Z5: =IF(OR(N5="〇",N5="○",N5="◯"),1,0) -> 0 | AA5: =IF(OR(O5="〇",O5="○",O5="◯"),1,0) -> 0 | AB5: =IF(OR(P5="〇",P5="○",P5="◯"),1,0) -> 0 | AC5: =IF(A5="","",IF(AA5=1,1,IF(Y5=1,2,IF(Z5=1,3,IF(AB5=1,4,5))))) -> 5 | AD5: =IF(A5="","",IF(K5="",'設定'!$C$37,K5)) -> 34.8 | AE5: =IF(A5="","",AC5*10000000-ROUND(ABS((AD5-'設定'!$C$37)/'設定'!$C$38)*10000,0)) -> 49979324 | AF5: =IF(A5="","",COUNTIF($AE$4:$AE$153,"<"&AE5)+COUNTIFS($AE$4:$AE$153,AE5,$A$4:$A$153,"<"&A5)+1) -> 30 | AG5: =IF(Q5="","",IFERROR(VALUE(LEFT(Q5,FIND(" ",Q5&" ")-1)),IFERROR(INDEX($A$4:$A$153,MATCH(Q5,$C$4:$C$153,0)),""))) | AH5: =IF(R5="","",IFERROR(VALUE(LEFT(R5,FIND(" ",R5&" ")-1)),IFERROR(INDEX($A$4:$A$153,MATCH(R5,$C$4:$C$153,0)),""))) | AI5: =IF(S5="","",IFERROR(VALUE(LEFT(S5,FIND(" ",S5&" ")-1)),IFERROR(INDEX($A$4:$A$153,MATCH(S5,$C$4:$C$153,0)),""))) | AJ5: =IF(OR(A5="",B5=""),"",IF(COUNTIFS($B$4:B5,B5,$A$4:A5,"<>")=1,MAX($AJ$3:AJ4)+1,"")) | AK5: =IF(OR(A5="",NOT(ISNUMBER(L5))),"",L5^2) -> 77.44 | AL5: =IF(OR(A5="",NOT(ISNUMBER(L5))),0,(L5-INDEX('計算'!$AE$7:$AG$7,X5))/INDEX('計算'!$AE$8:$AG$8,X5)) -> -0.10596535
A6: 2103 | B6: 1 | C6: 阿部 優奈 | D6: あべ ゆうな | E6: 女 | F6: 71 | G6: 66 | H6: 53 | I6: 62 | J6: 65 | K6: =IF(COUNT(F6:J6)=0,"",ROUND(AVERAGE(F6:J6),1)) -> 63.4 | L6: 7.4 | M6: × | U6: =IF(A6="","",INDEX('計算'!$Z$2:$Z$151,AF6)) -> 2 | V6: =IF(A6="","",IFERROR(IF(INDEX('②クラス編成'!$E$9:$E$158,MATCH(A6,'②クラス編成'!$D$9:$D$158,0))="","未",INDEX('②クラス編成'!$E$9:$E$158,MATCH(A6,'②クラス編成'!$D$9:$D$158,0))),"未")) -> 2 | W6: =IF(A6="","",A6&" "&C6) -> 2103 阿部 優奈 | X6: =IF(A6="","",IF(E6="男",1,IF(E6="女",2,3))) -> 2 | Y6: =IF(OR(M6="〇",M6="○",M6="◯"),1,0) -> 0 | Z6: =IF(OR(N6="〇",N6="○",N6="◯"),1,0) -> 0 | AA6: =IF(OR(O6="〇",O6="○",O6="◯"),1,0) -> 0 | AB6: =IF(OR(P6="〇",P6="○",P6="◯"),1,0) -> 0 | AC6: =IF(A6="","",IF(AA6=1,1,IF(Y6=1,2,IF(Z6=1,3,IF(AB6=1,4,5))))) -> 5 | AD6: =IF(A6="","",IF(K6="",'設定'!$C$37,K6)) -> 63.4 | AE6: =IF(A6="","",AC6*10000000-ROUND(ABS((AD6-'設定'!$C$37)/'設定'!$C$38)*10000,0)) -> 49999319 | AF6: =IF(A6="","",COUNTIF($AE$4:$AE$153,"<"&AE6)+COUNTIFS($AE$4:$AE$153,AE6,$A$4:$A$153,"<"&A6)+1) -> 99 | AG6: =IF(Q6="","",IFERROR(VALUE(LEFT(Q6,FIND(" ",Q6&" ")-1)),IFERROR(INDEX($A$4:$A$153,MATCH(Q6,$C$4:$C$153,0)),""))) | AH6: =IF(R6="","",IFERROR(VALUE(LEFT(R6,FIND(" ",R6&" ")-1)),IFERROR(INDEX($A$4:$A$153,MATCH(R6,$C$4:$C$153,0)),""))) | AI6: =IF(S6="","",IFERROR(VALUE(LEFT(S6,FIND(" ",S6&" ")-1)),IFERROR(INDEX($A$4:$A$153,MATCH(S6,$C$4:$C$153,0)),""))) | AJ6: =IF(OR(A6="",B6=""),"",IF(COUNTIFS($B$4:B6,B6,$A$4:A6,"<>")=1,MAX($AJ$3:AJ5)+1,"")) | AK6: =IF(OR(A6="",NOT(ISNUMBER(L6))),"",L6^2) -> 54.76 | AL6: =IF(OR(A6="",NOT(ISNUMBER(L6))),0,(L6-INDEX('計算'!$AE$7:$AG$7,X6))/INDEX('計算'!$AE$8:$AG$8,X6)) -> -2.3986703
A7: 2104 | B7: 1 | C7: 石井 彩花 | D7: いしい あやか | E7: 女 | F7: 42 | G7: 39 | H7: 40 | I7: 47 | J7: 49 | K7: =IF(COUNT(F7:J7)=0,"",ROUND(AVERAGE(F7:J7),1)) -> 43.4 | L7: 9.3 | M7: × | U7: =IF(A7="","",INDEX('計算'!$Z$2:$Z$151,AF7)) -> 1 | V7: =IF(A7="","",IFERROR(IF(INDEX('②クラス編成'!$E$9:$E$158,MATCH(A7,'②クラス編成'!$D$9:$D$158,0))="","未",INDEX('②クラス編成'!$E$9:$E$158,MATCH(A7,'②クラス編成'!$D$9:$D$158,0))),"未")) -> 1 | W7: =IF(A7="","",A7&" "&C7) -> 2104 石井 彩花 | X7: =IF(A7="","",IF(E7="男",1,IF(E7="女",2,3))) -> 2 | Y7: =IF(OR(M7="〇",M7="○",M7="◯"),1,0) -> 0 | Z7: =IF(OR(N7="〇",N7="○",N7="◯"),1,0) -> 0 | AA7: =IF(OR(O7="〇",O7="○",O7="◯"),1,0) -> 0 | AB7: =IF(OR(P7="〇",P7="○",P7="◯"),1,0) -> 0 | AC7: =IF(A7="","",IF(AA7=1,1,IF(Y7=1,2,IF(Z7=1,3,IF(AB7=1,4,5))))) -> 5 | AD7: =IF(A7="","",IF(K7="",'設定'!$C$37,K7)) -> 43.4 | AE7: =IF(A7="","",AC7*10000000-ROUND(ABS((AD7-'設定'!$C$37)/'設定'!$C$38)*10000,0)) -> 49985746 | AF7: =IF(A7="","",COUNTIF($AE$4:$AE$153,"<"&AE7)+COUNTIFS($AE$4:$AE$153,AE7,$A$4:$A$153,"<"&A7)+1) -> 36 | AG7: =IF(Q7="","",IFERROR(VALUE(LEFT(Q7,FIND(" ",Q7&" ")-1)),IFERROR(INDEX($A$4:$A$153,MATCH(Q7,$C$4:$C$153,0)),""))) | AH7: =IF(R7="","",IFERROR(VALUE(LEFT(R7,FIND(" ",R7&" ")-1)),IFERROR(INDEX($A$4:$A$153,MATCH(R7,$C$4:$C$153,0)),""))) | AI7: =IF(S7="","",IFERROR(VALUE(LEFT(S7,FIND(" ",S7&" ")-1)),IFERROR(INDEX($A$4:$A$153,MATCH(S7,$C$4:$C$153,0)),""))) | AJ7: =IF(OR(A7="",B7=""),"",IF(COUNTIFS($B$4:B7,B7,$A$4:A7,"<>")=1,MAX($AJ$3:AJ6)+1,"")) | AK7: =IF(OR(A7="",NOT(ISNUMBER(L7))),"",L7^2) -> 86.49 | AL7: =IF(OR(A7="",NOT(ISNUMBER(L7))),0,(L7-INDEX('計算'!$AE$7:$AG$7,X7))/INDEX('計算'!$AE$8:$AG$8,X7)) -> 0.71285784
A8: 2105 | B8: 1 | C8: 石井 駿 | D8: いしい しゅん | E8: 男 | F8: 40 | G8: 12 | H8: 17 | I8: 16 | J8: 12 | K8: =IF(COUNT(F8:J8)=0,"",ROUND(AVERAGE(F8:J8),1)) -> 19.4 | L8: 7.5 | M8: × | N8: 〇 | T8: 学級委員の経験あり | U8: =IF(A8="","",INDEX('計算'!$Z$2:$Z$151,AF8)) -> 2 | V8: =IF(A8="","",IFERROR(IF(INDEX('②クラス編成'!$E$9:$E$158,MATCH(A8,'②クラス編成'!$D$9:$D$158,0))="","未",INDEX('②クラス編成'!$E$9:$E$158,MATCH(A8,'②クラス編成'!$D$9:$D$158,0))),"未")) -> 2 | W8: =IF(A8="","",A8&" "&C8) -> 2105 石井 駿 | X8: =IF(A8="","",IF(E8="男",1,IF(E8="女",2,3))) -> 1 | Y8: =IF(OR(M8="〇",M8="○",M8="◯"),1,0) -> 0 | Z8: =IF(OR(N8="〇",N8="○",N8="◯"),1,0) -> 1 | AA8: =IF(OR(O8="〇",O8="○",O8="◯"),1,0) -> 0 | AB8: =IF(OR(P8="〇",P8="○",P8="◯"),1,0) -> 0 | AC8: =IF(A8="","",IF(AA8=1,1,IF(Y8=1,2,IF(Z8=1,3,IF(AB8=1,4,5))))) -> 3 | AD8: =IF(A8="","",IF(K8="",'設定'!$C$37,K8)) -> 19.4 | AE8: =IF(A8="","",AC8*10000000-ROUND(ABS((AD8-'設定'!$C$37)/'設定'!$C$38)*10000,0)) -> 29967823 | AF8: =IF(A8="","",COUNTIF($AE$4:$AE$153,"<"&AE8)+COUNTIFS($AE$4:$AE$153,AE8,$A$4:$A$153,"<"&A8)+1) -> 16 | AG8: =IF(Q8="","",IFERROR(VALUE(LEFT(Q8,FIND(" ",Q8&" ")-1)),IFERROR(INDEX($A$4:$A$153,MATCH(Q8,$C$4:$C$153,0)),""))) | AH8: =IF(R8="","",IFERROR(VALUE(LEFT(R8,FIND(" ",R8&" ")-1)),IFERROR(INDEX($A$4:$A$153,MATCH(R8,$C$4:$C$153,0)),""))) | AI8: =IF(S8="","",IFERROR(VALUE(LEFT(S8,FIND(" ",S8&" ")-1)),IFERROR(INDEX($A$4:$A$153,MATCH(S8,$C$4:$C$153,0)),""))) | AJ8: =IF(OR(A8="",B8=""),"",IF(COUNTIFS($B$4:B8,B8,$A$4:A8,"<>")=1,MAX($AJ$3:AJ7)+1,"")) | AK8: =IF(OR(A8="",NOT(ISNUMBER(L8))),"",L8^2) -> 56.25 | AL8: =IF(OR(A8="",NOT(ISNUMBER(L8))),0,(L8-INDEX('計算'!$AE$7:$AG$7,X8))/INDEX('計算'!$AE$8:$AG$8,X8)) -> -0.43410481
A9: 2106 | B9: 1 | C9: 石田 凛 | D9: いしだ りん | E9: 女 | F9: 92 | G9: 83 | H9: 76 | I9: 78 | J9: 64 | K9: =IF(COUNT(F9:J9)=0,"",ROUND(AVERAGE(F9:J9),1)) -> 78.6 | L9: 8.9 | M9: × | U9: =IF(A9="","",INDEX('計算'!$Z$2:$Z$151,AF9)) -> 3 | V9: =IF(A9="","",IFERROR(IF(INDEX('②クラス編成'!$E$9:$E$158,MATCH(A9,'②クラス編成'!$D$9:$D$158,0))="","未",INDEX('②クラス編成'!$E$9:$E$158,MATCH(A9,'②クラス編成'!$D$9:$D$158,0))),"未")) -> 3 | W9: =IF(A9="","",A9&" "&C9) -> 2106 石田 凛 | X9: =IF(A9="","",IF(E9="男",1,IF(E9="女",2,3))) -> 2 | Y9: =IF(OR(M9="〇",M9="○",M9="◯"),1,0) -> 0 | Z9: =IF(OR(N9="〇",N9="○",N9="◯"),1,0) -> 0 | AA9: =IF(OR(O9="〇",O9="○",O9="◯"),1,0) -> 0 | AB9: =IF(OR(P9="〇",P9="○",P9="◯"),1,0) -> 0 | AC9: =IF(A9="","",IF(AA9=1,1,IF(Y9=1,2,IF(Z9=1,3,IF(AB9=1,4,5))))) -> 5 | AD9: =IF(A9="","",IF(K9="",'設定'!$C$37,K9)) -> 78.6 | AE9: =IF(A9="","",AC9*10000000-ROUND(ABS((AD9-'設定'!$C$37)/'設定'!$C$38)*10000,0)) -> 49987968 | AF9: =IF(A9="","",COUNTIF($AE$4:$AE$153,"<"&AE9)+COUNTIFS($AE$4:$AE$153,AE9,$A$4:$A$153,"<"&A9)+1) -> 42 | AG9: =IF(Q9="","",IFERROR(VALUE(LEFT(Q9,FIND(" ",Q9&" ")-1)),IFERROR(INDEX($A$4:$A$153,MATCH(Q9,$C$4:$C$153,0)),""))) | AH9: =IF(R9="","",IFERROR(VALUE(LEFT(R9,FIND(" ",R9&" ")-1)),IFERROR(INDEX($A$4:$A$153,MATCH(R9,$C$4:$C$153,0)),""))) | AI9: =IF(S9="","",IFERROR(VALUE(LEFT(S9,FIND(" ",S9&" ")-1)),IFERROR(INDEX($A$4:$A$153,MATCH(S9,$C$4:$C$153,0)),""))) | AJ9: =IF(OR(A9="",B9=""),"",IF(COUNTIFS($B$4:B9,B9,$A$4:A9,"<>")=1,MAX($AJ$3:AJ8)+1,"")) | AK9: =IF(OR(A9="",NOT(ISNUMBER(L9))),"",L9^2) -> 79.21 | AL9: =IF(OR(A9="",NOT(ISNUMBER(L9))),0,(L9-INDEX('計算'!$AE$7:$AG$7,X9))/INDEX('計算'!$AE$8:$AG$8,X9)) -> 0.057799284
A10: 2107 | B10: 1 | C10: 井上 沙耶 | D10: いのうえ さや | E10: 女 | F10: 70 | G10: 85 | H10: 84 | I10: 76 | J10: 73 | K10: =IF(COUNT(F10:J10)=0,"",ROUND(AVERAGE(F10:J10),1)) -> 77.6 | L10: 9.9 | M10: × | U10: =IF(A10="","",INDEX('計算'!$Z$2:$Z$151,AF10)) -> 2 | V10: =IF(A10="","",IFERROR(IF(INDEX('②クラス編成'!$E$9:$E$158,MATCH(A10,'②クラス編成'!$D$9:$D$158,0))="","未",INDEX('②クラス編成'!$E$9:$E$158,MATCH(A10,'②クラス編成'!$D$9:$D$158,0))),"未")) -> 2 | W10: =IF(A10="","",A10&" "&C10) -> 2107 井上 沙耶 | X10: =IF(A10="","",IF(E10="男",1,IF(E10="女",2,3))) -> 2 | Y10: =IF(OR(M10="〇",M10="○",M10="◯"),1,0) -> 0 | Z10: =IF(OR(N10="〇",N10="○",N10="◯"),1,0) -> 0 | AA10: =IF(OR(O10="〇",O10="○",O10="◯"),1,0) -> 0 | AB10: =IF(OR(P10="〇",P10="○",P10="◯"),1,0) -> 0 | AC10: =IF(A10="","",IF(AA10=1,1,IF(Y10=1,2,IF(Z10=1,3,IF(AB10=1,4,5))))) -> 5 | AD10: =IF(A10="","",IF(K10="",'設定'!$C$37,K10)) -> 77.6 | AE10: =IF(A10="","",AC10*10000000-ROUND(ABS((AD10-'設定'!$C$37)/'設定'!$C$38)*10000,0)) -> 49988714 | AF10: =IF(A10="","",COUNTIF($AE$4:$AE$153,"<"&AE10)+COUNTIFS($AE$4:$AE$153,AE10,$A$4:$A$153,"<"&A10)+1) -> 47 | AG10: =IF(Q10="","",IFERROR(VALUE(LEFT(Q10,FIND(" ",Q10&" ")-1)),IFERROR(INDEX($A$4:$A$153,MATCH(Q10,$C$4:$C$153,0)),""))) | AH10: =IF(R10="","",IFERROR(VALUE(LEFT(R10,FIND(" ",R10&" ")-1)),IFERROR(INDEX($A$4:$A$153,MATCH(R10,$C$4:$C$153,0)),""))) | AI10: =IF(S10="","",IFERROR(VALUE(LEFT(S10,FIND(" ",S10&" ")-1)),IFERROR(INDEX($A$4:$A$153,MATCH(S10,$C$4:$C$153,0)),""))) | AJ10: =IF(OR(A10="",B10=""),"",IF(COUNTIFS($B$4:B10,B10,$A$4:A10,"<>")=1,MAX($AJ$3:AJ9)+1,"")) | AK10: =IF(OR(A10="",NOT(ISNUMBER(L10))),"",L10^2) -> 98.01 | AL10: =IF(OR(A10="",NOT(ISNUMBER(L10))),0,(L10-INDEX('計算'!$AE$7:$AG$7,X10))/INDEX('計算'!$AE$8:$AG$8,X10)) -> 1.6954457
A11: 2108 | B11: 1 | C11: 井上 陸 | D11: いのうえ りく | E11: 男 | F11: 45 | G11: 48 | H11: 42 | I11: 47 | J11: 57 | K11: =IF(COUNT(F11:J11)=0,"",ROUND(AVERAGE(F11:J11),1)) -> 47.8 | L11: 7 | M11: × | T11: 部活：陸上 | U11: =IF(A11="","",INDEX('計算'!$Z$2:$Z$151,AF11)) -> 1 | V11: =IF(A11="","",IFERROR(IF(INDEX('②クラス編成'!$E$9:$E$158,MATCH(A11,'②クラス編成'!$D$9:$D$158,0))="","未",INDEX('②クラス編成'!$E$9:$E$158,MATCH(A11,'②クラス編成'!$D$9:$D$158,0))),"未")) -> 1 | W11: =IF(A11="","",A11&" "&C11) -> 2108 井上 陸 | X11: =IF(A11="","",IF(E11="男",1,IF(E11="女",2,3))) -> 1 | Y11: =IF(OR(M11="〇",M11="○",M11="◯"),1,0) -> 0 | Z11: =IF(OR(N11="〇",N11="○",N11="◯"),1,0) -> 0 | AA11: =IF(OR(O11="〇",O11="○",O11="◯"),1,0) -> 0 | AB11: =IF(OR(P11="〇",P11="○",P11="◯"),1,0) -> 0 | AC11: =IF(A11="","",IF(AA11=1,1,IF(Y11=1,2,IF(Z11=1,3,IF(AB11=1,4,5))))) -> 5 | AD11: =IF(A11="","",IF(K11="",'設定'!$C$37,K11)) -> 47.8 | AE11: =IF(A11="","",AC11*10000000-ROUND(ABS((AD11-'設定'!$C$37)/'設定'!$C$38)*10000,0)) -> 49989032 | AF11: =IF(A11="","",COUNTIF($AE$4:$AE$153,"<"&AE11)+COUNTIFS($AE$4:$AE$153,AE11,$A$4:$A$153,"<"&A11)+1) -> 50 | AG11: =IF(Q11="","",IFERROR(VALUE(LEFT(Q11,FIND(" ",Q11&" ")-1)),IFERROR(INDEX($A$4:$A$153,MATCH(Q11,$C$4:$C$153,0)),""))) | AH11: =IF(R11="","",IFERROR(VALUE(LEFT(R11,FIND(" ",R11&" ")-1)),IFERROR(INDEX($A$4:$A$153,MATCH(R11,$C$4:$C$153,0)),""))) | AI11: =IF(S11="","",IFERROR(VALUE(LEFT(S11,FIND(" ",S11&" ")-1)),IFERROR(INDEX($A$4:$A$153,MATCH(S11,$C$4:$C$153,0)),""))) | AJ11: =IF(OR(A11="",B11=""),"",IF(COUNTIFS($B$4:B11,B11,$A$4:A11,"<>")=1,MAX($AJ$3:AJ10)+1,"")) | AK11: =IF(OR(A11="",NOT(ISNUMBER(L11))),"",L11^2) -> 49 | AL11: =IF(OR(A11="",NOT(ISNUMBER(L11))),0,(L11-INDEX('計算'!$AE$7:$AG$7,X11))/INDEX('計算'!$AE$8:$AG$8,X11)) -> -1.5720495
A12: 2109 | B12: 1 | C12: 江頭 智也 | D12: えがしら ともや | E12: 男 | F12: 76 | G12: 72 | H12: 67 | I12: 54 | J12: 42 | K12: =IF(COUNT(F12:J12)=0,"",ROUND(AVERAGE(F12:J12),1)) -> 62.2 | L12: 8 | M12: × | U12: =IF(A12="","",INDEX('計算'!$Z$2:$Z$151,AF12)) -> 3 | V12: =IF(A12="","",IFERROR(IF(INDEX('②クラス編成'!$E$9:$E$158,MATCH(A12,'②クラス編成'!$D$9:$D$158,0))="","未",INDEX('②クラス編成'!$E$9:$E$158,MATCH(A12,'②クラス編成'!$D$9:$D$158,0))),"未")) -> 3 | W12: =IF(A12="","",A12&" "&C12) -> 2109 江頭 智也 | X12: =IF(A12="","",IF(E12="男",1,IF(E12="女",2,3))) -> 1 | Y12: =IF(OR(M12="〇",M12="○",M12="◯"),1,0) -> 0 | Z12: =IF(OR(N12="〇",N12="○",N12="◯"),1,0) -> 0 | AA12: =IF(OR(O12="〇",O12="○",O12="◯"),1,0) -> 0 | AB12: =IF(OR(P12="〇",P12="○",P12="◯"),1,0) -> 0 | AC12: =IF(A12="","",IF(AA12=1,1,IF(Y12=1,2,IF(Z12=1,3,IF(AB12=1,4,5))))) -> 5 | AD12: =IF(A12="","",IF(K12="",'設定'!$C$37,K12)) -> 62.2 | AE12: =IF(A12="","",AC12*10000000-ROUND(ABS((AD12-'設定'!$C$37)/'設定'!$C$38)*10000,0)) -> 49999785 | AF12: =IF(A12="","",COUNTIF($AE$4:$AE$153,"<"&AE12)+COUNTIFS($AE$4:$AE$153,AE12,$A$4:$A$153,"<"&A12)+1) -> 104 | AG12: =IF(Q12="","",IFERROR(VALUE(LEFT(Q12,FIND(" ",Q12&" ")-1)),IFERROR(INDEX($A$4:$A$153,MATCH(Q12,$C$4:$C$153,0)),""))) | AH12: =IF(R12="","",IFERROR(VALUE(LEFT(R12,FIND(" ",R12&" ")-1)),IFERROR(INDEX($A$4:$A$153,MATCH(R12,$C$4:$C$153,0)),""))) | AI12: =IF(S12="","",IFERROR(VALUE(LEFT(S12,FIND(" ",S12&" ")-1)),IFERROR(INDEX($A$4:$A$153,MATCH(S12,$C$4:$C$153,0)),""))) | AJ12: =IF(OR(A12="",B12=""),"",IF(COUNTIFS($B$4:B12,B12,$A$4:A12,"<>")=1,MAX($AJ$3:AJ11)+1,"")) | AK12: =IF(OR(A12="",NOT(ISNUMBER(L12))),"",L12^2) -> 64 | AL12: =IF(OR(A12="",NOT(ISNUMBER(L12))),0,(L12-INDEX('計算'!$AE$7:$AG$7,X12))/INDEX('計算'!$AE$8:$AG$8,X12)) -> 0.70383984
A13: 2110 | B13: 1 | C13: 遠藤 大翔 | D13: えんどう ひろと | E13: 男 | F13: 80 | G13: 70 | H13: 59 | I13: 62 | J13: 57 | K13: =IF(COUNT(F13:J13)=0,"",ROUND(AVERAGE(F13:J13),1)) -> 65.6 | L13: 7.6 | M13: × | U13: =IF(A13="","",INDEX('計算'!$Z$2:$Z$151,AF13)) -> 1 | V13: =IF(A13="","",IFERROR(IF(INDEX('②クラス編成'!$E$9:$E$158,MATCH(A13,'②クラス編成'!$D$9:$D$158,0))="","未",INDEX('②クラス編成'!$E$9:$E$158,MATCH(A13,'②クラス編成'!$D$9:$D$158,0))),"未")) -> 1 | W13: =IF(A13="","",A13&" "&C13) -> 2110 遠藤 大翔 | X13: =IF(A13="","",IF(E13="男",1,IF(E13="女",2,3))) -> 1 | Y13: =IF(OR(M13="〇",M13="○",M13="◯"),1,0) -> 0 | Z13: =IF(OR(N13="〇",N13="○",N13="◯"),1,0) -> 0 | AA13: =IF(OR(O13="〇",O13="○",O13="◯"),1,0) -> 0 | AB13: =IF(OR(P13="〇",P13="○",P13="◯"),1,0) -> 0 | AC13: =IF(A13="","",IF(AA13=1,1,IF(Y13=1,2,IF(Z13=1,3,IF(AB13=1,4,5))))) -> 5 | AD13: =IF(A13="","",IF(K13="",'設定'!$C$37,K13)) -> 65.6 | AE13: =IF(A13="","",AC13*10000000-ROUND(ABS((AD13-'設定'!$C$37)/'設定'!$C$38)*10000,0)) -> 49997676 | AF13: =IF(A13="","",COUNTIF($AE$4:$AE$153,"<"&AE13)+COUNTIFS($AE$4:$AE$153,AE13,$A$4:$A$153,"<"&A13)+1) -> 92 | AG13: =IF(Q13="","",IFERROR(VALUE(LEFT(Q13,FIND(" ",Q13&" ")-1)),IFERROR(INDEX($A$4:$A$153,MATCH(Q13,$C$4:$C$153,0)),""))) | AH13: =IF(R13="","",IFERROR(VALUE(LEFT(R13,FIND(" ",R13&" ")-1)),IFERROR(INDEX($A$4:$A$153,MATCH(R13,$C$4:$C$153,0)),""))) | AI13: =IF(S13="","",IFERROR(VALUE(LEFT(S13,FIND(" ",S13&" ")-1)),IFERROR(INDEX($A$4:$A$153,MATCH(S13,$C$4:$C$153,0)),""))) | AJ13: =IF(OR(A13="",B13=""),"",IF(COUNTIFS($B$4:B13,B13,$A$4:A13,"<>")=1,MAX($AJ$3:AJ12)+1,"")) | AK13: =IF(OR(A13="",NOT(ISNUMBER(L13))),"",L13^2) -> 57.76 | AL13: =IF(OR(A13="",NOT(ISNUMBER(L13))),0,(L13-INDEX('計算'!$AE$7:$AG$7,X13))/INDEX('計算'!$AE$8:$AG$8,X13)) -> -0.20651588
A14: 2111 | B14: 1 | C14: 太田 大翔 | D14: おおた ひろと | E14: 男 | F14: 63 | G14: 66 | H14: 71 | I14: 79 | J14: 63 | K14: =IF(COUNT(F14:J14)=0,"",ROUND(AVERAGE(F14:J14),1)) -> 68.4 | L14: 8 | M14: × | U14: =IF(A14="","",INDEX('計算'!$Z$2:$Z$151,AF14)) -> 3 | V14: =IF(A14="","",IFERROR(IF(INDEX('②クラス編成'!$E$9:$E$158,MATCH(A14,'②クラス編成'!$D$9:$D$158,0))="","未",INDEX('②クラス編成'!$E$9:$E$158,MATCH(A14,'②クラス編成'!$D$9:$D$158,0))),"未")) -> 3 | W14: =IF(A14="","",A14&" "&C14) -> 2111 太田 大翔 | X14: =IF(A14="","",IF(E14="男",1,IF(E14="女",2,3))) -> 1 | Y14: =IF(OR(M14="〇",M14="○",M14="◯"),1,0) -> 0 | Z14: =IF(OR(N14="〇",N14="○",N14="◯"),1,0) -> 0 | AA14: =IF(OR(O14="〇",O14="○",O14="◯"),1,0) -> 0 | AB14: =IF(OR(P14="〇",P14="○",P14="◯"),1,0) -> 0 | AC14: =IF(A14="","",IF(AA14=1,1,IF(Y14=1,2,IF(Z14=1,3,IF(AB14=1,4,5))))) -> 5 | AD14: =IF(A14="","",IF(K14="",'設定'!$C$37,K14)) -> 68.4 | AE14: =IF(A14="","",AC14*10000000-ROUND(ABS((AD14-'設定'!$C$37)/'設定'!$C$38)*10000,0)) -> 49995585 | AF14: =IF(A14="","",COUNTIF($AE$4:$AE$153,"<"&AE14)+COUNTIFS($AE$4:$AE$153,AE14,$A$4:$A$153,"<"&A14)+1) -> 84 | AG14: =IF(Q14="","",IFERROR(VALUE(LEFT(Q14,FIND(" ",Q14&" ")-1)),IFERROR(INDEX($A$4:$A$153,MATCH(Q14,$C$4:$C$153,0)),""))) | AH14: =IF(R14="","",IFERROR(VALUE(LEFT(R14,FIND(" ",R14&" ")-1)),IFERROR(INDEX($A$4:$A$153,MATCH(R14,$C$4:$C$153,0)),""))) | AI14: =IF(S14="","",IFERROR(VALUE(LEFT(S14,FIND(" ",S14&" ")-1)),IFERROR(INDEX($A$4:$A$153,MATCH(S14,$C$4:$C$153,0)),""))) | AJ14: =IF(OR(A14="",B14=""),"",IF(COUNTIFS($B$4:B14,B14,$A$4:A14,"<>")=1,MAX($AJ$3:AJ13)+1,"")) | AK14: =IF(OR(A14="",NOT(ISNUMBER(L14))),"",L14^2) -> 64 | AL14: =IF(OR(A14="",NOT(ISNUMBER(L14))),0,(L14-INDEX('計算'!$AE$7:$AG$7,X14))/INDEX('計算'!$AE$8:$AG$8,X14)) -> 0.70383984
A15: 2112 | B15: 1 | C15: 加藤 航 | D15: かとう わたる | E15: 男 | F15: 66 | G15: 82 | H15: 70 | I15: 82 | J15: 83 | K15: =IF(COUNT(F15:J15)=0,"",ROUND(AVERAGE(F15:J15),1)) -> 76.6 | L15: 7.2 | M15: × | U15: =IF(A15="","",INDEX('計算'!$Z$2:$Z$151,AF15)) -> 1 | V15: =IF(A15="","",IFERROR(IF(INDEX('②クラス編成'!$E$9:$E$158,MATCH(A15,'②クラス編成'!$D$9:$D$158,0))="","未",INDEX('②クラス編成'!$E$9:$E$158,MATCH(A15,'②クラス編成'!$D$9:$D$158,0))),"未")) -> 1 | W15: =IF(A15="","",A15&" "&C15) -> 2112 加藤 航 | X15: =IF(A15="","",IF(E15="男",1,IF(E15="女",2,3))) -> 1 | Y15: =IF(OR(M15="〇",M15="○",M15="◯"),1,0) -> 0 | Z15: =IF(OR(N15="〇",N15="○",N15="◯"),1,0) -> 0 | AA15: =IF(OR(O15="〇",O15="○",O15="◯"),1,0) -> 0 | AB15: =IF(OR(P15="〇",P15="○",P15="◯"),1,0) -> 0 | AC15: =IF(A15="","",IF(AA15=1,1,IF(Y15=1,2,IF(Z15=1,3,IF(AB15=1,4,5))))) -> 5 | AD15: =IF(A15="","",IF(K15="",'設定'!$C$37,K15)) -> 76.6 | AE15: =IF(A15="","",AC15*10000000-ROUND(ABS((AD15-'設定'!$C$37)/'設定'!$C$38)*10000,0)) -> 49989461 | AF15: =IF(A15="","",COUNTIF($AE$4:$AE$153,"<"&AE15)+COUNTIFS($AE$4:$AE$153,AE15,$A$4:$A$153,"<"&A15)+1) -> 54 | AG15: =IF(Q15="","",IFERROR(VALUE(LEFT(Q15,FIND(" ",Q15&" ")-1)),IFERROR(INDEX($A$4:$A$153,MATCH(Q15,$C$4:$C$153,0)),""))) | AH15: =IF(R15="","",IFERROR(VALUE(LEFT(R15,FIND(" ",R15&" ")-1)),IFERROR(INDEX($A$4:$A$153,MATCH(R15,$C$4:$C$153,0)),""))) | AI15: =IF(S15="","",IFERROR(VALUE(LEFT(S15,FIND(" ",S15&" ")-1)),IFERROR(INDEX($A$4:$A$153,MATCH(S15,$C$4:$C$153,0)),""))) | AJ15: =IF(OR(A15="",B15=""),"",IF(COUNTIFS($B$4:B15,B15,$A$4:A15,"<>")=1,MAX($AJ$3:AJ14)+1,"")) | AK15: =IF(OR(A15="",NOT(ISNUMBER(L15))),"",L15^2) -> 51.84 | AL15: =IF(OR(A15="",NOT(ISNUMBER(L15))),0,(L15-INDEX('計算'!$AE$7:$AG$7,X15))/INDEX('計算'!$AE$8:$AG$8,X15)) -> -1.1168716
A16: 2113 | B16: 1 | C16: 北川 朝陽 | D16: きたがわ あさひ | E16: 男 | F16: 54 | G16: 47 | H16: 47 | I16: 38 | J16: 46 | K16: =IF(COUNT(F16:J16)=0,"",ROUND(AVERAGE(F16:J16),1)) -> 46.4 | L16: 6.6 | M16: × | U16: =IF(A16="","",INDEX('計算'!$Z$2:$Z$151,AF16)) -> 3 | V16: =IF(A16="","",IFERROR(IF(INDEX('②クラス編成'!$E$9:$E$158,MATCH(A16,'②クラス編成'!$D$9:$D$158,0))="","未",INDEX('②クラス編成'!$E$9:$E$158,MATCH(A16,'②クラス編成'!$D$9:$D$158,0))),"未")) -> 3 | W16: =IF(A16="","",A16&" "&C16) -> 2113 北川 朝陽 | X16: =IF(A16="","",IF(E16="男",1,IF(E16="女",2,3))) -> 1 | Y16: =IF(OR(M16="〇",M16="○",M16="◯"),1,0) -> 0 | Z16: =IF(OR(N16="〇",N16="○",N16="◯"),1,0) -> 0 | AA16: =IF(OR(O16="〇",O16="○",O16="◯"),1,0) -> 0 | AB16: =IF(OR(P16="〇",P16="○",P16="◯"),1,0) -> 0 | AC16: =IF(A16="","",IF(AA16=1,1,IF(Y16=1,2,IF(Z16=1,3,IF(AB16=1,4,5))))) -> 5 | AD16: =IF(A16="","",IF(K16="",'設定'!$C$37,K16)) -> 46.4 | AE16: =IF(A16="","",AC16*10000000-ROUND(ABS((AD16-'設定'!$C$37)/'設定'!$C$38)*10000,0)) -> 49987986 | AF16: =IF(A16="","",COUNTIF($AE$4:$AE$153,"<"&AE16)+COUNTIFS($AE$4:$AE$153,AE16,$A$4:$A$153,"<"&A16)+1) -> 44 | AG16: =IF(Q16="","",IFERROR(VALUE(LEFT(Q16,FIND(" ",Q16&" ")-1)),IFERROR(INDEX($A$4:$A$153,MATCH(Q16,$C$4:$C$153,0)),""))) | AH16: =IF(R16="","",IFERROR(VALUE(LEFT(R16,FIND(" ",R16&" ")-1)),IFERROR(INDEX($A$4:$A$153,MATCH(R16,$C$4:$C$153,0)),""))) | AI16: =IF(S16="","",IFERROR(VALUE(LEFT(S16,FIND(" ",S16&" ")-1)),IFERROR(INDEX($A$4:$A$153,MATCH(S16,$C$4:$C$153,0)),""))) | AJ16: =IF(OR(A16="",B16=""),"",IF(COUNTIFS($B$4:B16,B16,$A$4:A16,"<>")=1,MAX($AJ$3:AJ15)+1,"")) | AK16: =IF(OR(A16="",NOT(ISNUMBER(L16))),"",L16^2) -> 43.56 | AL16: =IF(OR(A16="",NOT(ISNUMBER(L16))),0,(L16-INDEX('計算'!$AE$7:$AG$7,X16))/INDEX('計算'!$AE$8:$AG$8,X16)) -> -2.4824052
A17: 2114 | B17: 1 | C17: 酒井 芽依 | D17: さかい めい | E17: 女 | F17: 58 | G17: 58 | H17: 46 | I17: 69 | J17: 53 | K17: =IF(COUNT(F17:J17)=0,"",ROUND(AVERAGE(F17:J17),1)) -> 56.8 | L17: 8.7 | M17: × | Q17: 2112 加藤 航 | R17: 2126 三浦 美桜 | U17: =IF(A17="","",INDEX('計算'!$Z$2:$Z$151,AF17)) -> 3 | V17: =IF(A17="","",IFERROR(IF(INDEX('②クラス編成'!$E$9:$E$158,MATCH(A17,'②クラス編成'!$D$9:$D$158,0))="","未",INDEX('②クラス編成'!$E$9:$E$158,MATCH(A17,'②クラス編成'!$D$9:$D$158,0))),"未")) -> 3 | W17: =IF(A17="","",A17&" "&C17) -> 2114 酒井 芽依 | X17: =IF(A17="","",IF(E17="男",1,IF(E17="女",2,3))) -> 2 | Y17: =IF(OR(M17="〇",M17="○",M17="◯"),1,0) -> 0 | Z17: =IF(OR(N17="〇",N17="○",N17="◯"),1,0) -> 0 | AA17: =IF(OR(O17="〇",O17="○",O17="◯"),1,0) -> 0 | AB17: =IF(OR(P17="〇",P17="○",P17="◯"),1,0) -> 0 | AC17: =IF(A17="","",IF(AA17=1,1,IF(Y17=1,2,IF(Z17=1,3,IF(AB17=1,4,5))))) -> 5 | AD17: =IF(A17="","",IF(K17="",'設定'!$C$37,K17)) -> 56.8 | AE17: =IF(A17="","",AC17*10000000-ROUND(ABS((AD17-'設定'!$C$37)/'設定'!$C$38)*10000,0)) -> 49995753 | AF17: =IF(A17="","",COUNTIF($AE$4:$AE$153,"<"&AE17)+COUNTIFS($AE$4:$AE$153,AE17,$A$4:$A$153,"<"&A17)+1) -> 86 | AG17: =IF(Q17="","",IFERROR(VALUE(LEFT(Q17,FIND(" ",Q17&" ")-1)),IFERROR(INDEX($A$4:$A$153,MATCH(Q17,$C$4:$C$153,0)),""))) -> 2112 | AH17: =IF(R17="","",IFERROR(VALUE(LEFT(R17,FIND(" ",R17&" ")-1)),IFERROR(INDEX($A$4:$A$153,MATCH(R17,$C$4:$C$153,0)),""))) -> 2126 | AI17: =IF(S17="","",IFERROR(VALUE(LEFT(S17,FIND(" ",S17&" ")-1)),IFERROR(INDEX($A$4:$A$153,MATCH(S17,$C$4:$C$153,0)),""))) | AJ17: =IF(OR(A17="",B17=""),"",IF(COUNTIFS($B$4:B17,B17,$A$4:A17,"<>")=1,MAX($AJ$3:AJ16)+1,"")) | AK17: =IF(OR(A17="",NOT(ISNUMBER(L17))),"",L17^2) -> 75.69 | AL17: =IF(OR(A17="",NOT(ISNUMBER(L17))),0,(L17-INDEX('計算'!$AE$7:$AG$7,X17))/INDEX('計算'!$AE$8:$AG$8,X17)) -> -0.26972999
A18: 2115 | B18: 1 | C18: 佐々木 理沙 | D18: ささき りさ | E18: 女 | F18: 63 | G18: 71 | H18: 68 | I18: 57 | J18: 72 | K18: =IF(COUNT(F18:J18)=0,"",ROUND(AVERAGE(F18:J18),1)) -> 66.2 | L18: 9.4 | M18: × | U18: =IF(A18="","",INDEX('計算'!$Z$2:$Z$151,AF18)) -> 3 | V18: =IF(A18="","",IFERROR(IF(INDEX('②クラス編成'!$E$9:$E$158,MATCH(A18,'②クラス編成'!$D$9:$D$158,0))="","未",INDEX('②クラス編成'!$E$9:$E$158,MATCH(A18,'②クラス編成'!$D$9:$D$158,0))),"未")) -> 3 | W18: =IF(A18="","",A18&" "&C18) -> 2115 佐々木 理沙 | X18: =IF(A18="","",IF(E18="男",1,IF(E18="女",2,3))) -> 2 | Y18: =IF(OR(M18="〇",M18="○",M18="◯"),1,0) -> 0 | Z18: =IF(OR(N18="〇",N18="○",N18="◯"),1,0) -> 0 | AA18: =IF(OR(O18="〇",O18="○",O18="◯"),1,0) -> 0 | AB18: =IF(OR(P18="〇",P18="○",P18="◯"),1,0) -> 0 | AC18: =IF(A18="","",IF(AA18=1,1,IF(Y18=1,2,IF(Z18=1,3,IF(AB18=1,4,5))))) -> 5 | AD18: =IF(A18="","",IF(K18="",'設定'!$C$37,K18)) -> 66.2 | AE18: =IF(A18="","",AC18*10000000-ROUND(ABS((AD18-'設定'!$C$37)/'設定'!$C$38)*10000,0)) -> 49997228 | AF18: =IF(A18="","",COUNTIF($AE$4:$AE$153,"<"&AE18)+COUNTIFS($AE$4:$AE$153,AE18,$A$4:$A$153,"<"&A18)+1) -> 88 | AG18: =IF(Q18="","",IFERROR(VALUE(LEFT(Q18,FIND(" ",Q18&" ")-1)),IFERROR(INDEX($A$4:$A$153,MATCH(Q18,$C$4:$C$153,0)),""))) | AH18: =IF(R18="","",IFERROR(VALUE(LEFT(R18,FIND(" ",R18&" ")-1)),IFERROR(INDEX($A$4:$A$153,MATCH(R18,$C$4:$C$153,0)),""))) | AI18: =IF(S18="","",IFERROR(VALUE(LEFT(S18,FIND(" ",S18&" ")-1)),IFERROR(INDEX($A$4:$A$153,MATCH(S18,$C$4:$C$153,0)),""))) | AJ18: =IF(OR(A18="",B18=""),"",IF(COUNTIFS($B$4:B18,B18,$A$4:A18,"<>")=1,MAX($AJ$3:AJ17)+1,"")) | AK18: =IF(OR(A18="",NOT(ISNUMBER(L18))),"",L18^2) -> 88.36 | AL18: =IF(OR(A18="",NOT(ISNUMBER(L18))),0,(L18-INDEX('計算'!$AE$7:$AG$7,X18))/INDEX('計算'!$AE$8:$AG$8,X18)) -> 0.87662247
A19: 2116 | B19: 1 | C19: 柴田 誠 | D19: しばた まこと | E19: 男 | F19: 36 | G19: 46 | H19: 42 | I19: 53 | J19: 62 | K19: =IF(COUNT(F19:J19)=0,"",ROUND(AVERAGE(F19:J19),1)) -> 47.8 | L19: 7.9 | M19: × | U19: =IF(A19="","",INDEX('計算'!$Z$2:$Z$151,AF19)) -> 2 | V19: =IF(A19="","",IFERROR(IF(INDEX('②クラス編成'!$E$9:$E$158,MATCH(A19,'②クラス編成'!$D$9:$D$158,0))="","未",INDEX('②クラス編成'!$E$9:$E$158,MATCH(A19,'②クラス編成'!$D$9:$D$158,0))),"未")) -> 2 | W19: =IF(A19="","",A19&" "&C19) -> 2116 柴田 誠 | X19: =IF(A19="","",IF(E19="男",1,IF(E19="女",2,3))) -> 1 | Y19: =IF(OR(M19="〇",M19="○",M19="◯"),1,0) -> 0 | Z19: =IF(OR(N19="〇",N19="○",N19="◯"),1,0) -> 0 | AA19: =IF(OR(O19="〇",O19="○",O19="◯"),1,0) -> 0 | AB19: =IF(OR(P19="〇",P19="○",P19="◯"),1,0) -> 0 | AC19: =IF(A19="","",IF(AA19=1,1,IF(Y19=1,2,IF(Z19=1,3,IF(AB19=1,4,5))))) -> 5 | AD19: =IF(A19="","",IF(K19="",'設定'!$C$37,K19)) -> 47.8 | AE19: =IF(A19="","",AC19*10000000-ROUND(ABS((AD19-'設定'!$C$37)/'設定'!$C$38)*10000,0)) -> 49989032 | AF19: =IF(A19="","",COUNTIF($AE$4:$AE$153,"<"&AE19)+COUNTIFS($AE$4:$AE$153,AE19,$A$4:$A$153,"<"&A19)+1) -> 51 | AG19: =IF(Q19="","",IFERROR(VALUE(LEFT(Q19,FIND(" ",Q19&" ")-1)),IFERROR(INDEX($A$4:$A$153,MATCH(Q19,$C$4:$C$153,0)),""))) | AH19: =IF(R19="","",IFERROR(VALUE(LEFT(R19,FIND(" ",R19&" ")-1)),IFERROR(INDEX($A$4:$A$153,MATCH(R19,$C$4:$C$153,0)),""))) | AI19: =IF(S19="","",IFERROR(VALUE(LEFT(S19,FIND(" ",S19&" ")-1)),IFERROR(INDEX($A$4:$A$153,MATCH(S19,$C$4:$C$153,0)),""))) | AJ19: =IF(OR(A19="",B19=""),"",IF(COUNTIFS($B$4:B19,B19,$A$4:A19,"<>")=1,MAX($AJ$3:AJ18)+1,"")) | AK19: =IF(OR(A19="",NOT(ISNUMBER(L19))),"",L19^2) -> 62.41 | AL19: =IF(OR(A19="",NOT(ISNUMBER(L19))),0,(L19-INDEX('計算'!$AE$7:$AG$7,X19))/INDEX('計算'!$AE$8:$AG$8,X19)) -> 0.47625091
A20: 2117 | B20: 1 | C20: 鈴木 誠 | D20: すずき まこと | E20: 男 | F20: 68 | G20: 71 | H20: 83 | I20: 55 | J20: 100 | K20: =IF(COUNT(F20:J20)=0,"",ROUND(AVERAGE(F20:J20),1)) -> 75.4 | L20: 7.4 | M20: × | P20: 〇 | U20: =IF(A20="","",INDEX('計算'!$Z$2:$Z$151,AF20)) -> 1 | V20: =IF(A20="","",IFERROR(IF(INDEX('②クラス編成'!$E$9:$E$158,MATCH(A20,'②クラス編成'!$D$9:$D$158,0))="","未",INDEX('②クラス編成'!$E$9:$E$158,MATCH(A20,'②クラス編成'!$D$9:$D$158,0))),"未")) -> 1 | W20: =IF(A20="","",A20&" "&C20) -> 2117 鈴木 誠 | X20: =IF(A20="","",IF(E20="男",1,IF(E20="女",2,3))) -> 1 | Y20: =IF(OR(M20="〇",M20="○",M20="◯"),1,0) -> 0 | Z20: =IF(OR(N20="〇",N20="○",N20="◯"),1,0) -> 0 | AA20: =IF(OR(O20="〇",O20="○",O20="◯"),1,0) -> 0 | AB20: =IF(OR(P20="〇",P20="○",P20="◯"),1,0) -> 1 | AC20: =IF(A20="","",IF(AA20=1,1,IF(Y20=1,2,IF(Z20=1,3,IF(AB20=1,4,5))))) -> 4 | AD20: =IF(A20="","",IF(K20="",'設定'!$C$37,K20)) -> 75.4 | AE20: =IF(A20="","",AC20*10000000-ROUND(ABS((AD20-'設定'!$C$37)/'設定'!$C$38)*10000,0)) -> 39990357 | AF20: =IF(A20="","",COUNTIF($AE$4:$AE$153,"<"&AE20)+COUNTIFS($AE$4:$AE$153,AE20,$A$4:$A$153,"<"&A20)+1) -> 27 | AG20: =IF(Q20="","",IFERROR(VALUE(LEFT(Q20,FIND(" ",Q20&" ")-1)),IFERROR(INDEX($A$4:$A$153,MATCH(Q20,$C$4:$C$153,0)),""))) | AH20: =IF(R20="","",IFERROR(VALUE(LEFT(R20,FIND(" ",R20&" ")-1)),IFERROR(INDEX($A$4:$A$153,MATCH(R20,$C$4:$C$153,0)),""))) | AI20: =IF(S20="","",IFERROR(VALUE(LEFT(S20,FIND(" ",S20&" ")-1)),IFERROR(INDEX($A$4:$A$153,MATCH(S20,$C$4:$C$153,0)),""))) | AJ20: =IF(OR(A20="",B20=""),"",IF(COUNTIFS($B$4:B20,B20,$A$4:A20,"<>")=1,MAX($AJ$3:AJ19)+1,"")) | AK20: =IF(OR(A20="",NOT(ISNUMBER(L20))),"",L20^2) -> 54.76 | AL20: =IF(OR(A20="",NOT(ISNUMBER(L20))),0,(L20-INDEX('計算'!$AE$7:$AG$7,X20))/INDEX('計算'!$AE$8:$AG$8,X20)) -> -0.66169374
A21: 2118 | B21: 1 | C21: 鈴木 悠真 | D21: すずき ゆうま | E21: 男 | F21: 68 | G21: 56 | H21: 59 | I21: 54 | J21: 58 | K21: =IF(COUNT(F21:J21)=0,"",ROUND(AVERAGE(F21:J21),1)) -> 59 | L21: 7.4 | M21: × | U21: =IF(A21="","",INDEX('計算'!$Z$2:$Z$151,AF21)) -> 3 | V21: =IF(A21="","",IFERROR(IF(INDEX('②クラス編成'!$E$9:$E$158,MATCH(A21,'②クラス編成'!$D$9:$D$158,0))="","未",INDEX('②クラス編成'!$E$9:$E$158,MATCH(A21,'②クラス編成'!$D$9:$D$158,0))),"未")) -> 3 | W21: =IF(A21="","",A21&" "&C21) -> 2118 鈴木 悠真 | X21: =IF(A21="","",IF(E21="男",1,IF(E21="女",2,3))) -> 1 | Y21: =IF(OR(M21="〇",M21="○",M21="◯"),1,0) -> 0 | Z21: =IF(OR(N21="〇",N21="○",N21="◯"),1,0) -> 0 | AA21: =IF(OR(O21="〇",O21="○",O21="◯"),1,0) -> 0 | AB21: =IF(OR(P21="〇",P21="○",P21="◯"),1,0) -> 0 | AC21: =IF(A21="","",IF(AA21=1,1,IF(Y21=1,2,IF(Z21=1,3,IF(AB21=1,4,5))))) -> 5 | AD21: =IF(A21="","",IF(K21="",'設定'!$C$37,K21)) -> 59 | AE21: =IF(A21="","",AC21*10000000-ROUND(ABS((AD21-'設定'!$C$37)/'設定'!$C$38)*10000,0)) -> 49997396 | AF21: =IF(A21="","",COUNTIF($AE$4:$AE$153,"<"&AE21)+COUNTIFS($AE$4:$AE$153,AE21,$A$4:$A$153,"<"&A21)+1) -> 90 | AG21: =IF(Q21="","",IFERROR(VALUE(LEFT(Q21,FIND(" ",Q21&" ")-1)),IFERROR(INDEX($A$4:$A$153,MATCH(Q21,$C$4:$C$153,0)),""))) | AH21: =IF(R21="","",IFERROR(VALUE(LEFT(R21,FIND(" ",R21&" ")-1)),IFERROR(INDEX($A$4:$A$153,MATCH(R21,$C$4:$C$153,0)),""))) | AI21: =IF(S21="","",IFERROR(VALUE(LEFT(S21,FIND(" ",S21&" ")-1)),IFERROR(INDEX($A$4:$A$153,MATCH(S21,$C$4:$C$153,0)),""))) | AJ21: =IF(OR(A21="",B21=""),"",IF(COUNTIFS($B$4:B21,B21,$A$4:A21,"<>")=1,MAX($AJ$3:AJ20)+1,"")) | AK21: =IF(OR(A21="",NOT(ISNUMBER(L21))),"",L21^2) -> 54.76 | AL21: =IF(OR(A21="",NOT(ISNUMBER(L21))),0,(L21-INDEX('計算'!$AE$7:$AG$7,X21))/INDEX('計算'!$AE$8:$AG$8,X21)) -> -0.66169374
A22: 2119 | B22: 1 | C22: 高橋 紬 | D22: たかはし つむぎ | E22: 女 | F22: 49 | G22: 48 | H22: 67 | I22: 40 | J22: 62 | K22: =IF(COUNT(F22:J22)=0,"",ROUND(AVERAGE(F22:J22),1)) -> 53.2 | L22: 9.5 | M22: × | U22: =IF(A22="","",INDEX('計算'!$Z$2:$Z$151,AF22)) -> 1 | V22: =IF(A22="","",IFERROR(IF(INDEX('②クラス編成'!$E$9:$E$158,MATCH(A22,'②クラス編成'!$D$9:$D$158,0))="","未",INDEX('②クラス編成'!$E$9:$E$158,MATCH(A22,'②クラス編成'!$D$9:$D$158,0))),"未")) -> 1 | W22: =IF(A22="","",A22&" "&C22) -> 2119 高橋 紬 | X22: =IF(A22="","",IF(E22="男",1,IF(E22="女",2,3))) -> 2 | Y22: =IF(OR(M22="〇",M22="○",M22="◯"),1,0) -> 0 | Z22: =IF(OR(N22="〇",N22="○",N22="◯"),1,0) -> 0 | AA22: =IF(OR(O22="〇",O22="○",O22="◯"),1,0) -> 0 | AB22: =IF(OR(P22="〇",P22="○",P22="◯"),1,0) -> 0 | AC22: =IF(A22="","",IF(AA22=1,1,IF(Y22=1,2,IF(Z22=1,3,IF(AB22=1,4,5))))) -> 5 | AD22: =IF(A22="","",IF(K22="",'設定'!$C$37,K22)) -> 53.2 | AE22: =IF(A22="","",AC22*10000000-ROUND(ABS((AD22-'設定'!$C$37)/'設定'!$C$38)*10000,0)) -> 49993064 | AF22: =IF(A22="","",COUNTIF($AE$4:$AE$153,"<"&AE22)+COUNTIFS($AE$4:$AE$153,AE22,$A$4:$A$153,"<"&A22)+1) -> 74 | AG22: =IF(Q22="","",IFERROR(VALUE(LEFT(Q22,FIND(" ",Q22&" ")-1)),IFERROR(INDEX($A$4:$A$153,MATCH(Q22,$C$4:$C$153,0)),""))) | AH22: =IF(R22="","",IFERROR(VALUE(LEFT(R22,FIND(" ",R22&" ")-1)),IFERROR(INDEX($A$4:$A$153,MATCH(R22,$C$4:$C$153,0)),""))) | AI22: =IF(S22="","",IFERROR(VALUE(LEFT(S22,FIND(" ",S22&" ")-1)),IFERROR(INDEX($A$4:$A$153,MATCH(S22,$C$4:$C$153,0)),""))) | AJ22: =IF(OR(A22="",B22=""),"",IF(COUNTIFS($B$4:B22,B22,$A$4:A22,"<>")=1,MAX($AJ$3:AJ21)+1,"")) | AK22: =IF(OR(A22="",NOT(ISNUMBER(L22))),"",L22^2) -> 90.25 | AL22: =IF(OR(A22="",NOT(ISNUMBER(L22))),0,(L22-INDEX('計算'!$AE$7:$AG$7,X22))/INDEX('計算'!$AE$8:$AG$8,X22)) -> 1.0403871
A23: 2120 | B23: 1 | C23: 田中 隼人 | D23: たなか はやと | E23: 男 | F23: 68 | G23: 77 | H23: 67 | I23: 66 | J23: 60 | K23: =IF(COUNT(F23:J23)=0,"",ROUND(AVERAGE(F23:J23),1)) -> 67.6 | L23: 7.3 | M23: × | O23: 〇 | U23: =IF(A23="","",INDEX('計算'!$Z$2:$Z$151,AF23)) -> 2 | V23: =IF(A23="","",IFERROR(IF(INDEX('②クラス編成'!$E$9:$E$158,MATCH(A23,'②クラス編成'!$D$9:$D$158,0))="","未",INDEX('②クラス編成'!$E$9:$E$158,MATCH(A23,'②クラス編成'!$D$9:$D$158,0))),"未")) -> 2 | W23: =IF(A23="","",A23&" "&C23) -> 2120 田中 隼人 | X23: =IF(A23="","",IF(E23="男",1,IF(E23="女",2,3))) -> 1 | Y23: =IF(OR(M23="〇",M23="○",M23="◯"),1,0) -> 0 | Z23: =IF(OR(N23="〇",N23="○",N23="◯"),1,0) -> 0 | AA23: =IF(OR(O23="〇",O23="○",O23="◯"),1,0) -> 1 | AB23: =IF(OR(P23="〇",P23="○",P23="◯"),1,0) -> 0 | AC23: =IF(A23="","",IF(AA23=1,1,IF(Y23=1,2,IF(Z23=1,3,IF(AB23=1,4,5))))) -> 1 | AD23: =IF(A23="","",IF(K23="",'設定'!$C$37,K23)) -> 67.6 | AE23: =IF(A23="","",AC23*10000000-ROUND(ABS((AD23-'設定'!$C$37)/'設定'!$C$38)*10000,0)) -> 9996182 | AF23: =IF(A23="","",COUNTIF($AE$4:$AE$153,"<"&AE23)+COUNTIFS($AE$4:$AE$153,AE23,$A$4:$A$153,"<"&A23)+1) -> 5 | AG23: =IF(Q23="","",IFERROR(VALUE(LEFT(Q23,FIND(" ",Q23&" ")-1)),IFERROR(INDEX($A$4:$A$153,MATCH(Q23,$C$4:$C$153,0)),""))) | AH23: =IF(R23="","",IFERROR(VALUE(LEFT(R23,FIND(" ",R23&" ")-1)),IFERROR(INDEX($A$4:$A$153,MATCH(R23,$C$4:$C$153,0)),""))) | AI23: =IF(S23="","",IFERROR(VALUE(LEFT(S23,FIND(" ",S23&" ")-1)),IFERROR(INDEX($A$4:$A$153,MATCH(S23,$C$4:$C$153,0)),""))) | AJ23: =IF(OR(A23="",B23=""),"",IF(COUNTIFS($B$4:B23,B23,$A$4:A23,"<>")=1,MAX($AJ$3:AJ22)+1,"")) | AK23: =IF(OR(A23="",NOT(ISNUMBER(L23))),"",L23^2) -> 53.29 | AL23: =IF(OR(A23="",NOT(ISNUMBER(L23))),0,(L23-INDEX('計算'!$AE$7:$AG$7,X23))/INDEX('計算'!$AE$8:$AG$8,X23)) -> -0.88928267
A24: 2121 | B24: 1 | C24: 田中 陽葵 | D24: たなか ひまり | E24: 女 | F24: 49 | G24: 47 | H24: 57 | I24: 65 | J24: 65 | K24: =IF(COUNT(F24:J24)=0,"",ROUND(AVERAGE(F24:J24),1)) -> 56.6 | L24: 8 | M24: × | U24: =IF(A24="","",INDEX('計算'!$Z$2:$Z$151,AF24)) -> 1 | V24: =IF(A24="","",IFERROR(IF(INDEX('②クラス編成'!$E$9:$E$158,MATCH(A24,'②クラス編成'!$D$9:$D$158,0))="","未",INDEX('②クラス編成'!$E$9:$E$158,MATCH(A24,'②クラス編成'!$D$9:$D$158,0))),"未")) -> 1 | W24: =IF(A24="","",A24&" "&C24) -> 2121 田中 陽葵 | X24: =IF(A24="","",IF(E24="男",1,IF(E24="女",2,3))) -> 2 | Y24: =IF(OR(M24="〇",M24="○",M24="◯"),1,0) -> 0 | Z24: =IF(OR(N24="〇",N24="○",N24="◯"),1,0) -> 0 | AA24: =IF(OR(O24="〇",O24="○",O24="◯"),1,0) -> 0 | AB24: =IF(OR(P24="〇",P24="○",P24="◯"),1,0) -> 0 | AC24: =IF(A24="","",IF(AA24=1,1,IF(Y24=1,2,IF(Z24=1,3,IF(AB24=1,4,5))))) -> 5 | AD24: =IF(A24="","",IF(K24="",'設定'!$C$37,K24)) -> 56.6 | AE24: =IF(A24="","",AC24*10000000-ROUND(ABS((AD24-'設定'!$C$37)/'設定'!$C$38)*10000,0)) -> 49995603 | AF24: =IF(A24="","",COUNTIF($AE$4:$AE$153,"<"&AE24)+COUNTIFS($AE$4:$AE$153,AE24,$A$4:$A$153,"<"&A24)+1) -> 85 | AG24: =IF(Q24="","",IFERROR(VALUE(LEFT(Q24,FIND(" ",Q24&" ")-1)),IFERROR(INDEX($A$4:$A$153,MATCH(Q24,$C$4:$C$153,0)),""))) | AH24: =IF(R24="","",IFERROR(VALUE(LEFT(R24,FIND(" ",R24&" ")-1)),IFERROR(INDEX($A$4:$A$153,MATCH(R24,$C$4:$C$153,0)),""))) | AI24: =IF(S24="","",IFERROR(VALUE(LEFT(S24,FIND(" ",S24&" ")-1)),IFERROR(INDEX($A$4:$A$153,MATCH(S24,$C$4:$C$153,0)),""))) | AJ24: =IF(OR(A24="",B24=""),"",IF(COUNTIFS($B$4:B24,B24,$A$4:A24,"<>")=1,MAX($AJ$3:AJ23)+1,"")) | AK24: =IF(OR(A24="",NOT(ISNUMBER(L24))),"",L24^2) -> 64 | AL24: =IF(OR(A24="",NOT(ISNUMBER(L24))),0,(L24-INDEX('計算'!$AE$7:$AG$7,X24))/INDEX('計算'!$AE$8:$AG$8,X24)) -> -1.4160825
A25: 2122 | B25: 1 | C25: 中村 楓 | D25: なかむら かえで | E25: 女 | F25: 38 | G25: 54 | H25: 64 | I25: 54 | J25: 41 | K25: =IF(COUNT(F25:J25)=0,"",ROUND(AVERAGE(F25:J25),1)) -> 50.2 | L25: 9.3 | M25: × | U25: =IF(A25="","",INDEX('計算'!$Z$2:$Z$151,AF25)) -> 1 | V25: =IF(A25="","",IFERROR(IF(INDEX('②クラス編成'!$E$9:$E$158,MATCH(A25,'②クラス編成'!$D$9:$D$158,0))="","未",INDEX('②クラス編成'!$E$9:$E$158,MATCH(A25,'②クラス編成'!$D$9:$D$158,0))),"未")) -> 1 | W25: =IF(A25="","",A25&" "&C25) -> 2122 中村 楓 | X25: =IF(A25="","",IF(E25="男",1,IF(E25="女",2,3))) -> 2 | Y25: =IF(OR(M25="〇",M25="○",M25="◯"),1,0) -> 0 | Z25: =IF(OR(N25="〇",N25="○",N25="◯"),1,0) -> 0 | AA25: =IF(OR(O25="〇",O25="○",O25="◯"),1,0) -> 0 | AB25: =IF(OR(P25="〇",P25="○",P25="◯"),1,0) -> 0 | AC25: =IF(A25="","",IF(AA25=1,1,IF(Y25=1,2,IF(Z25=1,3,IF(AB25=1,4,5))))) -> 5 | AD25: =IF(A25="","",IF(K25="",'設定'!$C$37,K25)) -> 50.2 | AE25: =IF(A25="","",AC25*10000000-ROUND(ABS((AD25-'設定'!$C$37)/'設定'!$C$38)*10000,0)) -> 49990824 | AF25: =IF(A25="","",COUNTIF($AE$4:$AE$153,"<"&AE25)+COUNTIFS($AE$4:$AE$153,AE25,$A$4:$A$153,"<"&A25)+1) -> 61 | AG25: =IF(Q25="","",IFERROR(VALUE(LEFT(Q25,FIND(" ",Q25&" ")-1)),IFERROR(INDEX($A$4:$A$153,MATCH(Q25,$C$4:$C$153,0)),""))) | AH25: =IF(R25="","",IFERROR(VALUE(LEFT(R25,FIND(" ",R25&" ")-1)),IFERROR(INDEX($A$4:$A$153,MATCH(R25,$C$4:$C$153,0)),""))) | AI25: =IF(S25="","",IFERROR(VALUE(LEFT(S25,FIND(" ",S25&" ")-1)),IFERROR(INDEX($A$4:$A$153,MATCH(S25,$C$4:$C$153,0)),""))) | AJ25: =IF(OR(A25="",B25=""),"",IF(COUNTIFS($B$4:B25,B25,$A$4:A25,"<>")=1,MAX($AJ$3:AJ24)+1,"")) | AK25: =IF(OR(A25="",NOT(ISNUMBER(L25))),"",L25^2) -> 86.49 | AL25: =IF(OR(A25="",NOT(ISNUMBER(L25))),0,(L25-INDEX('計算'!$AE$7:$AG$7,X25))/INDEX('計算'!$AE$8:$AG$8,X25)) -> 0.71285784
A26: 2123 | B26: 1 | C26: 原田 杏 | D26: はらだ あん | E26: 女 | F26: 53 | G26: 59 | H26: 55 | I26: 73 | J26: 62 | K26: =IF(COUNT(F26:J26)=0,"",ROUND(AVERAGE(F26:J26),1)) -> 60.4 | L26: 9 | M26: × | N26: 〇 | U26: =IF(A26="","",INDEX('計算'!$Z$2:$Z$151,AF26)) -> 2 | V26: =IF(A26="","",IFERROR(IF(INDEX('②クラス編成'!$E$9:$E$158,MATCH(A26,'②クラス編成'!$D$9:$D$158,0))="","未",INDEX('②クラス編成'!$E$9:$E$158,MATCH(A26,'②クラス編成'!$D$9:$D$158,0))),"未")) -> 2 | W26: =IF(A26="","",A26&" "&C26) -> 2123 原田 杏 | X26: =IF(A26="","",IF(E26="男",1,IF(E26="女",2,3))) -> 2 | Y26: =IF(OR(M26="〇",M26="○",M26="◯"),1,0) -> 0 | Z26: =IF(OR(N26="〇",N26="○",N26="◯"),1,0) -> 1 | AA26: =IF(OR(O26="〇",O26="○",O26="◯"),1,0) -> 0 | AB26: =IF(OR(P26="〇",P26="○",P26="◯"),1,0) -> 0 | AC26: =IF(A26="","",IF(AA26=1,1,IF(Y26=1,2,IF(Z26=1,3,IF(AB26=1,4,5))))) -> 3 | AD26: =IF(A26="","",IF(K26="",'設定'!$C$37,K26)) -> 60.4 | AE26: =IF(A26="","",AC26*10000000-ROUND(ABS((AD26-'設定'!$C$37)/'設定'!$C$38)*10000,0)) -> 29998441 | AF26: =IF(A26="","",COUNTIF($AE$4:$AE$153,"<"&AE26)+COUNTIFS($AE$4:$AE$153,AE26,$A$4:$A$153,"<"&A26)+1) -> 24 | AG26: =IF(Q26="","",IFERROR(VALUE(LEFT(Q26,FIND(" ",Q26&" ")-1)),IFERROR(INDEX($A$4:$A$153,MATCH(Q26,$C$4:$C$153,0)),""))) | AH26: =IF(R26="","",IFERROR(VALUE(LEFT(R26,FIND(" ",R26&" ")-1)),IFERROR(INDEX($A$4:$A$153,MATCH(R26,$C$4:$C$153,0)),""))) | AI26: =IF(S26="","",IFERROR(VALUE(LEFT(S26,FIND(" ",S26&" ")-1)),IFERROR(INDEX($A$4:$A$153,MATCH(S26,$C$4:$C$153,0)),""))) | AJ26: =IF(OR(A26="",B26=""),"",IF(COUNTIFS($B$4:B26,B26,$A$4:A26,"<>")=1,MAX($AJ$3:AJ25)+1,"")) | AK26: =IF(OR(A26="",NOT(ISNUMBER(L26))),"",L26^2) -> 81 | AL26: =IF(OR(A26="",NOT(ISNUMBER(L26))),0,(L26-INDEX('計算'!$AE$7:$AG$7,X26))/INDEX('計算'!$AE$8:$AG$8,X26)) -> 0.22156392
A27: 2124 | B27: 1 | C27: 前田 奏太 | D27: まえだ かなた | E27: 男 | F27: 80 | G27: 76 | H27: 78 | I27: 73 | J27: 71 | K27: =IF(COUNT(F27:J27)=0,"",ROUND(AVERAGE(F27:J27),1)) -> 75.6 | L27: 8 | M27: × | Q27: 2102 阿部 陽葵 | U27: =IF(A27="","",INDEX('計算'!$Z$2:$Z$151,AF27)) -> 2 | V27: =IF(A27="","",IFERROR(IF(INDEX('②クラス編成'!$E$9:$E$158,MATCH(A27,'②クラス編成'!$D$9:$D$158,0))="","未",INDEX('②クラス編成'!$E$9:$E$158,MATCH(A27,'②クラス編成'!$D$9:$D$158,0))),"未")) -> 2 | W27: =IF(A27="","",A27&" "&C27) -> 2124 前田 奏太 | X27: =IF(A27="","",IF(E27="男",1,IF(E27="女",2,3))) -> 1 | Y27: =IF(OR(M27="〇",M27="○",M27="◯"),1,0) -> 0 | Z27: =IF(OR(N27="〇",N27="○",N27="◯"),1,0) -> 0 | AA27: =IF(OR(O27="〇",O27="○",O27="◯"),1,0) -> 0 | AB27: =IF(OR(P27="〇",P27="○",P27="◯"),1,0) -> 0 | AC27: =IF(A27="","",IF(AA27=1,1,IF(Y27=1,2,IF(Z27=1,3,IF(AB27=1,4,5))))) -> 5 | AD27: =IF(A27="","",IF(K27="",'設定'!$C$37,K27)) -> 75.6 | AE27: =IF(A27="","",AC27*10000000-ROUND(ABS((AD27-'設定'!$C$37)/'設定'!$C$38)*10000,0)) -> 49990208 | AF27: =IF(A27="","",COUNTIF($AE$4:$AE$153,"<"&AE27)+COUNTIFS($AE$4:$AE$153,AE27,$A$4:$A$153,"<"&A27)+1) -> 57 | AG27: =IF(Q27="","",IFERROR(VALUE(LEFT(Q27,FIND(" ",Q27&" ")-1)),IFERROR(INDEX($A$4:$A$153,MATCH(Q27,$C$4:$C$153,0)),""))) -> 2102 | AH27: =IF(R27="","",IFERROR(VALUE(LEFT(R27,FIND(" ",R27&" ")-1)),IFERROR(INDEX($A$4:$A$153,MATCH(R27,$C$4:$C$153,0)),""))) | AI27: =IF(S27="","",IFERROR(VALUE(LEFT(S27,FIND(" ",S27&" ")-1)),IFERROR(INDEX($A$4:$A$153,MATCH(S27,$C$4:$C$153,0)),""))) | AJ27: =IF(OR(A27="",B27=""),"",IF(COUNTIFS($B$4:B27,B27,$A$4:A27,"<>")=1,MAX($AJ$3:AJ26)+1,"")) | AK27: =IF(OR(A27="",NOT(ISNUMBER(L27))),"",L27^2) -> 64 | AL27: =IF(OR(A27="",NOT(ISNUMBER(L27))),0,(L27-INDEX('計算'!$AE$7:$AG$7,X27))/INDEX('計算'!$AE$8:$AG$8,X27)) -> 0.70383984
A28: 2125 | B28: 1 | C28: 前田 颯太 | D28: まえだ そうた | E28: 男 | F28: 47 | G28: 58 | H28: 46 | I28: 44 | J28: 62 | K28: =IF(COUNT(F28:J28)=0,"",ROUND(AVERAGE(F28:J28),1)) -> 51.4 | L28: 8.1 | M28: × | O28: 〇 | U28: =IF(A28="","",INDEX('計算'!$Z$2:$Z$151,AF28)) -> 1 | V28: =IF(A28="","",IFERROR(IF(INDEX('②クラス編成'!$E$9:$E$158,MATCH(A28,'②クラス編成'!$D$9:$D$158,0))="","未",INDEX('②クラス編成'!$E$9:$E$158,MATCH(A28,'②クラス編成'!$D$9:$D$158,0))),"未")) -> 1 | W28: =IF(A28="","",A28&" "&C28) -> 2125 前田 颯太 | X28: =IF(A28="","",IF(E28="男",1,IF(E28="女",2,3))) -> 1 | Y28: =IF(OR(M28="〇",M28="○",M28="◯"),1,0) -> 0 | Z28: =IF(OR(N28="〇",N28="○",N28="◯"),1,0) -> 0 | AA28: =IF(OR(O28="〇",O28="○",O28="◯"),1,0) -> 1 | AB28: =IF(OR(P28="〇",P28="○",P28="◯"),1,0) -> 0 | AC28: =IF(A28="","",IF(AA28=1,1,IF(Y28=1,2,IF(Z28=1,3,IF(AB28=1,4,5))))) -> 1 | AD28: =IF(A28="","",IF(K28="",'設定'!$C$37,K28)) -> 51.4 | AE28: =IF(A28="","",AC28*10000000-ROUND(ABS((AD28-'設定'!$C$37)/'設定'!$C$38)*10000,0)) -> 9991720 | AF28: =IF(A28="","",COUNTIF($AE$4:$AE$153,"<"&AE28)+COUNTIFS($AE$4:$AE$153,AE28,$A$4:$A$153,"<"&A28)+1) -> 4 | AG28: =IF(Q28="","",IFERROR(VALUE(LEFT(Q28,FIND(" ",Q28&" ")-1)),IFERROR(INDEX($A$4:$A$153,MATCH(Q28,$C$4:$C$153,0)),""))) | AH28: =IF(R28="","",IFERROR(VALUE(LEFT(R28,FIND(" ",R28&" ")-1)),IFERROR(INDEX($A$4:$A$153,MATCH(R28,$C$4:$C$153,0)),""))) | AI28: =IF(S28="","",IFERROR(VALUE(LEFT(S28,FIND(" ",S28&" ")-1)),IFERROR(INDEX($A$4:$A$153,MATCH(S28,$C$4:$C$153,0)),""))) | AJ28: =IF(OR(A28="",B28=""),"",IF(COUNTIFS($B$4:B28,B28,$A$4:A28,"<>")=1,MAX($AJ$3:AJ27)+1,"")) | AK28: =IF(OR(A28="",NOT(ISNUMBER(L28))),"",L28^2) -> 65.61 | AL28: =IF(OR(A28="",NOT(ISNUMBER(L28))),0,(L28-INDEX('計算'!$AE$7:$AG$7,X28))/INDEX('計算'!$AE$8:$AG$8,X28)) -> 0.93142877
A29: 2126 | B29: 1 | C29: 三浦 美桜 | D29: みうら みお | E29: 女 | F29: 56 | G29: 63 | H29: 55 | I29: 58 | J29: 59 | K29: =IF(COUNT(F29:J29)=0,"",ROUND(AVERAGE(F29:J29),1)) -> 58.2 | L29: 9.7 | M29: × | U29: =IF(A29="","",INDEX('計算'!$Z$2:$Z$151,AF29)) -> 2 | V29: =IF(A29="","",IFERROR(IF(INDEX('②クラス編成'!$E$9:$E$158,MATCH(A29,'②クラス編成'!$D$9:$D$158,0))="","未",INDEX('②クラス編成'!$E$9:$E$158,MATCH(A29,'②クラス編成'!$D$9:$D$158,0))),"未")) -> 2 | W29: =IF(A29="","",A29&" "&C29) -> 2126 三浦 美桜 | X29: =IF(A29="","",IF(E29="男",1,IF(E29="女",2,3))) -> 2 | Y29: =IF(OR(M29="〇",M29="○",M29="◯"),1,0) -> 0 | Z29: =IF(OR(N29="〇",N29="○",N29="◯"),1,0) -> 0 | AA29: =IF(OR(O29="〇",O29="○",O29="◯"),1,0) -> 0 | AB29: =IF(OR(P29="〇",P29="○",P29="◯"),1,0) -> 0 | AC29: =IF(A29="","",IF(AA29=1,1,IF(Y29=1,2,IF(Z29=1,3,IF(AB29=1,4,5))))) -> 5 | AD29: =IF(A29="","",IF(K29="",'設定'!$C$37,K29)) -> 58.2 | AE29: =IF(A29="","",AC29*10000000-ROUND(ABS((AD29-'設定'!$C$37)/'設定'!$C$38)*10000,0)) -> 49996798 | AF29: =IF(A29="","",COUNTIF($AE$4:$AE$153,"<"&AE29)+COUNTIFS($AE$4:$AE$153,AE29,$A$4:$A$153,"<"&A29)+1) -> 87 | AG29: =IF(Q29="","",IFERROR(VALUE(LEFT(Q29,FIND(" ",Q29&" ")-1)),IFERROR(INDEX($A$4:$A$153,MATCH(Q29,$C$4:$C$153,0)),""))) | AH29: =IF(R29="","",IFERROR(VALUE(LEFT(R29,FIND(" ",R29&" ")-1)),IFERROR(INDEX($A$4:$A$153,MATCH(R29,$C$4:$C$153,0)),""))) | AI29: =IF(S29="","",IFERROR(VALUE(LEFT(S29,FIND(" ",S29&" ")-1)),IFERROR(INDEX($A$4:$A$153,MATCH(S29,$C$4:$C$153,0)),""))) | AJ29: =IF(OR(A29="",B29=""),"",IF(COUNTIFS($B$4:B29,B29,$A$4:A29,"<>")=1,MAX($AJ$3:AJ28)+1,"")) | AK29: =IF(OR(A29="",NOT(ISNUMBER(L29))),"",L29^2) -> 94.09 | AL29: =IF(OR(A29="",NOT(ISNUMBER(L29))),0,(L29-INDEX('計算'!$AE$7:$AG$7,X29))/INDEX('計算'!$AE$8:$AG$8,X29)) -> 1.3679164
A30: 2127 | B30: 1 | C30: 宮崎 奏太 | D30: みやざき かなた | E30: 男 | F30: 57 | G30: 48 | H30: 33 | I30: 61 | J30: 40 | K30: =IF(COUNT(F30:J30)=0,"",ROUND(AVERAGE(F30:J30),1)) -> 47.8 | L30: 7.8 | M30: × | U30: =IF(A30="","",INDEX('計算'!$Z$2:$Z$151,AF30)) -> 3 | V30: =IF(A30="","",IFERROR(IF(INDEX('②クラス編成'!$E$9:$E$158,MATCH(A30,'②クラス編成'!$D$9:$D$158,0))="","未",INDEX('②クラス編成'!$E$9:$E$158,MATCH(A30,'②クラス編成'!$D$9:$D$158,0))),"未")) -> 3 | W30: =IF(A30="","",A30&" "&C30) -> 2127 宮崎 奏太 | X30: =IF(A30="","",IF(E30="男",1,IF(E30="女",2,3))) -> 1 | Y30: =IF(OR(M30="〇",M30="○",M30="◯"),1,0) -> 0 | Z30: =IF(OR(N30="〇",N30="○",N30="◯"),1,0) -> 0 | AA30: =IF(OR(O30="〇",O30="○",O30="◯"),1,0) -> 0 | AB30: =IF(OR(P30="〇",P30="○",P30="◯"),1,0) -> 0 | AC30: =IF(A30="","",IF(AA30=1,1,IF(Y30=1,2,IF(Z30=1,3,IF(AB30=1,4,5))))) -> 5 | AD30: =IF(A30="","",IF(K30="",'設定'!$C$37,K30)) -> 47.8 | AE30: =IF(A30="","",AC30*10000000-ROUND(ABS((AD30-'設定'!$C$37)/'設定'!$C$38)*10000,0)) -> 49989032 | AF30: =IF(A30="","",COUNTIF($AE$4:$AE$153,"<"&AE30)+COUNTIFS($AE$4:$AE$153,AE30,$A$4:$A$153,"<"&A30)+1) -> 52 | AG30: =IF(Q30="","",IFERROR(VALUE(LEFT(Q30,FIND(" ",Q30&" ")-1)),IFERROR(INDEX($A$4:$A$153,MATCH(Q30,$C$4:$C$153,0)),""))) | AH30: =IF(R30="","",IFERROR(VALUE(LEFT(R30,FIND(" ",R30&" ")-1)),IFERROR(INDEX($A$4:$A$153,MATCH(R30,$C$4:$C$153,0)),""))) | AI30: =IF(S30="","",IFERROR(VALUE(LEFT(S30,FIND(" ",S30&" ")-1)),IFERROR(INDEX($A$4:$A$153,MATCH(S30,$C$4:$C$153,0)),""))) | AJ30: =IF(OR(A30="",B30=""),"",IF(COUNTIFS($B$4:B30,B30,$A$4:A30,"<>")=1,MAX($AJ$3:AJ29)+1,"")) | AK30: =IF(OR(A30="",NOT(ISNUMBER(L30))),"",L30^2) -> 60.84 | AL30: =IF(OR(A30="",NOT(ISNUMBER(L30))),0,(L30-INDEX('計算'!$AE$7:$AG$7,X30))/INDEX('計算'!$AE$8:$AG$8,X30)) -> 0.24866198
A31: 2128 | B31: 1 | C31: 宮崎 圭吾 | D31: みやざき けいご | E31: 男 | F31: 55 | G31: 44 | H31: 57 | I31: 54 | J31: 53 | K31: =IF(COUNT(F31:J31)=0,"",ROUND(AVERAGE(F31:J31),1)) -> 52.6 | L31: 7.9 | M31: × | Q31: 2133 山崎 遥 | U31: =IF(A31="","",INDEX('計算'!$Z$2:$Z$151,AF31)) -> 3 | V31: =IF(A31="","",IFERROR(IF(INDEX('②クラス編成'!$E$9:$E$158,MATCH(A31,'②クラス編成'!$D$9:$D$158,0))="","未",INDEX('②クラス編成'!$E$9:$E$158,MATCH(A31,'②クラス編成'!$D$9:$D$158,0))),"未")) -> 3 | W31: =IF(A31="","",A31&" "&C31) -> 2128 宮崎 圭吾 | X31: =IF(A31="","",IF(E31="男",1,IF(E31="女",2,3))) -> 1 | Y31: =IF(OR(M31="〇",M31="○",M31="◯"),1,0) -> 0 | Z31: =IF(OR(N31="〇",N31="○",N31="◯"),1,0) -> 0 | AA31: =IF(OR(O31="〇",O31="○",O31="◯"),1,0) -> 0 | AB31: =IF(OR(P31="〇",P31="○",P31="◯"),1,0) -> 0 | AC31: =IF(A31="","",IF(AA31=1,1,IF(Y31=1,2,IF(Z31=1,3,IF(AB31=1,4,5))))) -> 5 | AD31: =IF(A31="","",IF(K31="",'設定'!$C$37,K31)) -> 52.6 | AE31: =IF(A31="","",AC31*10000000-ROUND(ABS((AD31-'設定'!$C$37)/'設定'!$C$38)*10000,0)) -> 49992616 | AF31: =IF(A31="","",COUNTIF($AE$4:$AE$153,"<"&AE31)+COUNTIFS($AE$4:$AE$153,AE31,$A$4:$A$153,"<"&A31)+1) -> 72 | AG31: =IF(Q31="","",IFERROR(VALUE(LEFT(Q31,FIND(" ",Q31&" ")-1)),IFERROR(INDEX($A$4:$A$153,MATCH(Q31,$C$4:$C$153,0)),""))) -> 2133 | AH31: =IF(R31="","",IFERROR(VALUE(LEFT(R31,FIND(" ",R31&" ")-1)),IFERROR(INDEX($A$4:$A$153,MATCH(R31,$C$4:$C$153,0)),""))) | AI31: =IF(S31="","",IFERROR(VALUE(LEFT(S31,FIND(" ",S31&" ")-1)),IFERROR(INDEX($A$4:$A$153,MATCH(S31,$C$4:$C$153,0)),""))) | AJ31: =IF(OR(A31="",B31=""),"",IF(COUNTIFS($B$4:B31,B31,$A$4:A31,"<>")=1,MAX($AJ$3:AJ30)+1,"")) | AK31: =IF(OR(A31="",NOT(ISNUMBER(L31))),"",L31^2) -> 62.41 | AL31: =IF(OR(A31="",NOT(ISNUMBER(L31))),0,(L31-INDEX('計算'!$AE$7:$AG$7,X31))/INDEX('計算'!$AE$8:$AG$8,X31)) -> 0.47625091
A32: 2129 | B32: 1 | C32: 宮崎 直樹 | D32: みやざき なおき | E32: 男 | F32: 47 | G32: 43 | H32: 50 | I32: 59 | J32: 65 | K32: =IF(COUNT(F32:J32)=0,"",ROUND(AVERAGE(F32:J32),1)) -> 52.8 | L32: 7.5 | M32: × | T32: 生徒会 | U32: =IF(A32="","",INDEX('計算'!$Z$2:$Z$151,AF32)) -> 2 | V32: =IF(A32="","",IFERROR(IF(INDEX('②クラス編成'!$E$9:$E$158,MATCH(A32,'②クラス編成'!$D$9:$D$158,0))="","未",INDEX('②クラス編成'!$E$9:$E$158,MATCH(A32,'②クラス編成'!$D$9:$D$158,0))),"未")) -> 2 | W32: =IF(A32="","",A32&" "&C32) -> 2129 宮崎 直樹 | X32: =IF(A32="","",IF(E32="男",1,IF(E32="女",2,3))) -> 1 | Y32: =IF(OR(M32="〇",M32="○",M32="◯"),1,0) -> 0 | Z32: =IF(OR(N32="〇",N32="○",N32="◯"),1,0) -> 0 | AA32: =IF(OR(O32="〇",O32="○",O32="◯"),1,0) -> 0 | AB32: =IF(OR(P32="〇",P32="○",P32="◯"),1,0) -> 0 | AC32: =IF(A32="","",IF(AA32=1,1,IF(Y32=1,2,IF(Z32=1,3,IF(AB32=1,4,5))))) -> 5 | AD32: =IF(A32="","",IF(K32="",'設定'!$C$37,K32)) -> 52.8 | AE32: =IF(A32="","",AC32*10000000-ROUND(ABS((AD32-'設定'!$C$37)/'設定'!$C$38)*10000,0)) -> 49992766 | AF32: =IF(A32="","",COUNTIF($AE$4:$AE$153,"<"&AE32)+COUNTIFS($AE$4:$AE$153,AE32,$A$4:$A$153,"<"&A32)+1) -> 73 | AG32: =IF(Q32="","",IFERROR(VALUE(LEFT(Q32,FIND(" ",Q32&" ")-1)),IFERROR(INDEX($A$4:$A$153,MATCH(Q32,$C$4:$C$153,0)),""))) | AH32: =IF(R32="","",IFERROR(VALUE(LEFT(R32,FIND(" ",R32&" ")-1)),IFERROR(INDEX($A$4:$A$153,MATCH(R32,$C$4:$C$153,0)),""))) | AI32: =IF(S32="","",IFERROR(VALUE(LEFT(S32,FIND(" ",S32&" ")-1)),IFERROR(INDEX($A$4:$A$153,MATCH(S32,$C$4:$C$153,0)),""))) | AJ32: =IF(OR(A32="",B32=""),"",IF(COUNTIFS($B$4:B32,B32,$A$4:A32,"<>")=1,MAX($AJ$3:AJ31)+1,"")) | AK32: =IF(OR(A32="",NOT(ISNUMBER(L32))),"",L32^2) -> 56.25 | AL32: =IF(OR(A32="",NOT(ISNUMBER(L32))),0,(L32-INDEX('計算'!$AE$7:$AG$7,X32))/INDEX('計算'!$AE$8:$AG$8,X32)) -> -0.43410481
A33: 2130 | B33: 1 | C33: 森 愛莉 | D33: もり あいり | E33: 女 | F33: 66 | G33: 53 | H33: 63 | I33: 72 | J33: 63 | K33: =IF(COUNT(F33:J33)=0,"",ROUND(AVERAGE(F33:J33),1)) -> 63.4 | L33: 8.6 | M33: × | Q33: 2123 原田 杏 | U33: =IF(A33="","",INDEX('計算'!$Z$2:$Z$151,AF33)) -> 3 | V33: =IF(A33="","",IFERROR(IF(INDEX('②クラス編成'!$E$9:$E$158,MATCH(A33,'②クラス編成'!$D$9:$D$158,0))="","未",INDEX('②クラス編成'!$E$9:$E$158,MATCH(A33,'②クラス編成'!$D$9:$D$158,0))),"未")) -> 3 | W33: =IF(A33="","",A33&" "&C33) -> 2130 森 愛莉 | X33: =IF(A33="","",IF(E33="男",1,IF(E33="女",2,3))) -> 2 | Y33: =IF(OR(M33="〇",M33="○",M33="◯"),1,0) -> 0 | Z33: =IF(OR(N33="〇",N33="○",N33="◯"),1,0) -> 0 | AA33: =IF(OR(O33="〇",O33="○",O33="◯"),1,0) -> 0 | AB33: =IF(OR(P33="〇",P33="○",P33="◯"),1,0) -> 0 | AC33: =IF(A33="","",IF(AA33=1,1,IF(Y33=1,2,IF(Z33=1,3,IF(AB33=1,4,5))))) -> 5 | AD33: =IF(A33="","",IF(K33="",'設定'!$C$37,K33)) -> 63.4 | AE33: =IF(A33="","",AC33*10000000-ROUND(ABS((AD33-'設定'!$C$37)/'設定'!$C$38)*10000,0)) -> 49999319 | AF33: =IF(A33="","",COUNTIF($AE$4:$AE$153,"<"&AE33)+COUNTIFS($AE$4:$AE$153,AE33,$A$4:$A$153,"<"&A33)+1) -> 100 | AG33: =IF(Q33="","",IFERROR(VALUE(LEFT(Q33,FIND(" ",Q33&" ")-1)),IFERROR(INDEX($A$4:$A$153,MATCH(Q33,$C$4:$C$153,0)),""))) -> 2123 | AH33: =IF(R33="","",IFERROR(VALUE(LEFT(R33,FIND(" ",R33&" ")-1)),IFERROR(INDEX($A$4:$A$153,MATCH(R33,$C$4:$C$153,0)),""))) | AI33: =IF(S33="","",IFERROR(VALUE(LEFT(S33,FIND(" ",S33&" ")-1)),IFERROR(INDEX($A$4:$A$153,MATCH(S33,$C$4:$C$153,0)),""))) | AJ33: =IF(OR(A33="",B33=""),"",IF(COUNTIFS($B$4:B33,B33,$A$4:A33,"<>")=1,MAX($AJ$3:AJ32)+1,"")) | AK33: =IF(OR(A33="",NOT(ISNUMBER(L33))),"",L33^2) -> 73.96 | AL33: =IF(OR(A33="",NOT(ISNUMBER(L33))),0,(L33-INDEX('計算'!$AE$7:$AG$7,X33))/INDEX('計算'!$AE$8:$AG$8,X33)) -> -0.43349463
A34: 2131 | B34: 1 | C34: 森田 杏 | D34: もりた あん | E34: 女 | F34: 55 | G34: 55 | H34: 62 | I34: 54 | J34: 85 | K34: =IF(COUNT(F34:J34)=0,"",ROUND(AVERAGE(F34:J34),1)) -> 62.2 | L34: 9.6 | M34: × | U34: =IF(A34="","",INDEX('計算'!$Z$2:$Z$151,AF34)) -> 1 | V34: =IF(A34="","",IFERROR(IF(INDEX('②クラス編成'!$E$9:$E$158,MATCH(A34,'②クラス編成'!$D$9:$D$158,0))="","未",INDEX('②クラス編成'!$E$9:$E$158,MATCH(A34,'②クラス編成'!$D$9:$D$158,0))),"未")) -> 1 | W34: =IF(A34="","",A34&" "&C34) -> 2131 森田 杏 | X34: =IF(A34="","",IF(E34="男",1,IF(E34="女",2,3))) -> 2 | Y34: =IF(OR(M34="〇",M34="○",M34="◯"),1,0) -> 0 | Z34: =IF(OR(N34="〇",N34="○",N34="◯"),1,0) -> 0 | AA34: =IF(OR(O34="〇",O34="○",O34="◯"),1,0) -> 0 | AB34: =IF(OR(P34="〇",P34="○",P34="◯"),1,0) -> 0 | AC34: =IF(A34="","",IF(AA34=1,1,IF(Y34=1,2,IF(Z34=1,3,IF(AB34=1,4,5))))) -> 5 | AD34: =IF(A34="","",IF(K34="",'設定'!$C$37,K34)) -> 62.2 | AE34: =IF(A34="","",AC34*10000000-ROUND(ABS((AD34-'設定'!$C$37)/'設定'!$C$38)*10000,0)) -> 49999785 | AF34: =IF(A34="","",COUNTIF($AE$4:$AE$153,"<"&AE34)+COUNTIFS($AE$4:$AE$153,AE34,$A$4:$A$153,"<"&A34)+1) -> 105 | AG34: =IF(Q34="","",IFERROR(VALUE(LEFT(Q34,FIND(" ",Q34&" ")-1)),IFERROR(INDEX($A$4:$A$153,MATCH(Q34,$C$4:$C$153,0)),""))) | AH34: =IF(R34="","",IFERROR(VALUE(LEFT(R34,FIND(" ",R34&" ")-1)),IFERROR(INDEX($A$4:$A$153,MATCH(R34,$C$4:$C$153,0)),""))) | AI34: =IF(S34="","",IFERROR(VALUE(LEFT(S34,FIND(" ",S34&" ")-1)),IFERROR(INDEX($A$4:$A$153,MATCH(S34,$C$4:$C$153,0)),""))) | AJ34: =IF(OR(A34="",B34=""),"",IF(COUNTIFS($B$4:B34,B34,$A$4:A34,"<>")=1,MAX($AJ$3:AJ33)+1,"")) | AK34: =IF(OR(A34="",NOT(ISNUMBER(L34))),"",L34^2) -> 92.16 | AL34: =IF(OR(A34="",NOT(ISNUMBER(L34))),0,(L34-INDEX('計算'!$AE$7:$AG$7,X34))/INDEX('計算'!$AE$8:$AG$8,X34)) -> 1.2041518
A35: 2132 | B35: 1 | C35: 森田 心春 | D35: もりた こはる | E35: 女 | F35: 66 | G35: 76 | H35: 69 | I35: 74 | J35: 79 | K35: =IF(COUNT(F35:J35)=0,"",ROUND(AVERAGE(F35:J35),1)) -> 72.8 | L35: 8 | M35: × | N35: 〇 | U35: =IF(A35="","",INDEX('計算'!$Z$2:$Z$151,AF35)) -> 2 | V35: =IF(A35="","",IFERROR(IF(INDEX('②クラス編成'!$E$9:$E$158,MATCH(A35,'②クラス編成'!$D$9:$D$158,0))="","未",INDEX('②クラス編成'!$E$9:$E$158,MATCH(A35,'②クラス編成'!$D$9:$D$158,0))),"未")) -> 2 | W35: =IF(A35="","",A35&" "&C35) -> 2132 森田 心春 | X35: =IF(A35="","",IF(E35="男",1,IF(E35="女",2,3))) -> 2 | Y35: =IF(OR(M35="〇",M35="○",M35="◯"),1,0) -> 0 | Z35: =IF(OR(N35="〇",N35="○",N35="◯"),1,0) -> 1 | AA35: =IF(OR(O35="〇",O35="○",O35="◯"),1,0) -> 0 | AB35: =IF(OR(P35="〇",P35="○",P35="◯"),1,0) -> 0 | AC35: =IF(A35="","",IF(AA35=1,1,IF(Y35=1,2,IF(Z35=1,3,IF(AB35=1,4,5))))) -> 3 | AD35: =IF(A35="","",IF(K35="",'設定'!$C$37,K35)) -> 72.8 | AE35: =IF(A35="","",AC35*10000000-ROUND(ABS((AD35-'設定'!$C$37)/'設定'!$C$38)*10000,0)) -> 29992299 | AF35: =IF(A35="","",COUNTIF($AE$4:$AE$153,"<"&AE35)+COUNTIFS($AE$4:$AE$153,AE35,$A$4:$A$153,"<"&A35)+1) -> 21 | AG35: =IF(Q35="","",IFERROR(VALUE(LEFT(Q35,FIND(" ",Q35&" ")-1)),IFERROR(INDEX($A$4:$A$153,MATCH(Q35,$C$4:$C$153,0)),""))) | AH35: =IF(R35="","",IFERROR(VALUE(LEFT(R35,FIND(" ",R35&" ")-1)),IFERROR(INDEX($A$4:$A$153,MATCH(R35,$C$4:$C$153,0)),""))) | AI35: =IF(S35="","",IFERROR(VALUE(LEFT(S35,FIND(" ",S35&" ")-1)),IFERROR(INDEX($A$4:$A$153,MATCH(S35,$C$4:$C$153,0)),""))) | AJ35: =IF(OR(A35="",B35=""),"",IF(COUNTIFS($B$4:B35,B35,$A$4:A35,"<>")=1,MAX($AJ$3:AJ34)+1,"")) | AK35: =IF(OR(A35="",NOT(ISNUMBER(L35))),"",L35^2) -> 64 | AL35: =IF(OR(A35="",NOT(ISNUMBER(L35))),0,(L35-INDEX('計算'!$AE$7:$AG$7,X35))/INDEX('計算'!$AE$8:$AG$8,X35)) -> -1.4160825
A36: 2133 | B36: 1 | C36: 山崎 遥 | D36: やまざき はるか | E36: 女 | F36: 41 | G36: 50 | H36: 45 | I36: 61 | J36: 50 | K36: =IF(COUNT(F36:J36)=0,"",ROUND(AVERAGE(F36:J36),1)) -> 49.4 | L36: 8.7 | M36: × | U36: =IF(A36="","",INDEX('計算'!$Z$2:$Z$151,AF36)) -> 2 | V36: =IF(A36="","",IFERROR(IF(INDEX('②クラス編成'!$E$9:$E$158,MATCH(A36,'②クラス編成'!$D$9:$D$158,0))="","未",INDEX('②クラス編成'!$E$9:$E$158,MATCH(A36,'②クラス編成'!$D$9:$D$158,0))),"未")) -> 2 | W36: =IF(A36="","",A36&" "&C36) -> 2133 山崎 遥 | X36: =IF(A36="","",IF(E36="男",1,IF(E36="女",2,3))) -> 2 | Y36: =IF(OR(M36="〇",M36="○",M36="◯"),1,0) -> 0 | Z36: =IF(OR(N36="〇",N36="○",N36="◯"),1,0) -> 0 | AA36: =IF(OR(O36="〇",O36="○",O36="◯"),1,0) -> 0 | AB36: =IF(OR(P36="〇",P36="○",P36="◯"),1,0) -> 0 | AC36: =IF(A36="","",IF(AA36=1,1,IF(Y36=1,2,IF(Z36=1,3,IF(AB36=1,4,5))))) -> 5 | AD36: =IF(A36="","",IF(K36="",'設定'!$C$37,K36)) -> 49.4 | AE36: =IF(A36="","",AC36*10000000-ROUND(ABS((AD36-'設定'!$C$37)/'設定'!$C$38)*10000,0)) -> 49990227 | AF36: =IF(A36="","",COUNTIF($AE$4:$AE$153,"<"&AE36)+COUNTIFS($AE$4:$AE$153,AE36,$A$4:$A$153,"<"&A36)+1) -> 58 | AG36: =IF(Q36="","",IFERROR(VALUE(LEFT(Q36,FIND(" ",Q36&" ")-1)),IFERROR(INDEX($A$4:$A$153,MATCH(Q36,$C$4:$C$153,0)),""))) | AH36: =IF(R36="","",IFERROR(VALUE(LEFT(R36,FIND(" ",R36&" ")-1)),IFERROR(INDEX($A$4:$A$153,MATCH(R36,$C$4:$C$153,0)),""))) | AI36: =IF(S36="","",IFERROR(VALUE(LEFT(S36,FIND(" ",S36&" ")-1)),IFERROR(INDEX($A$4:$A$153,MATCH(S36,$C$4:$C$153,0)),""))) | AJ36: =IF(OR(A36="",B36=""),"",IF(COUNTIFS($B$4:B36,B36,$A$4:A36,"<>")=1,MAX($AJ$3:AJ35)+1,"")) | AK36: =IF(OR(A36="",NOT(ISNUMBER(L36))),"",L36^2) -> 75.69 | AL36: =IF(OR(A36="",NOT(ISNUMBER(L36))),0,(L36-INDEX('計算'!$AE$7:$AG$7,X36))/INDEX('計算'!$AE$8:$AG$8,X36)) -> -0.26972999
A37: 2134 | B37: 1 | C37: 山下 律 | D37: やました りつ | E37: 男 | F37: 87 | G37: 94 | H37: 74 | I37: 87 | J37: 76 | K37: =IF(COUNT(F37:J37)=0,"",ROUND(AVERAGE(F37:J37),1)) -> 83.6 | L37: 7 | M37: 〇 | U37: =IF(A37="","",INDEX('計算'!$Z$2:$Z$151,AF37)) -> 2 | V37: =IF(A37="","",IFERROR(IF(INDEX('②クラス編成'!$E$9:$E$158,MATCH(A37,'②クラス編成'!$D$9:$D$158,0))="","未",INDEX('②クラス編成'!$E$9:$E$158,MATCH(A37,'②クラス編成'!$D$9:$D$158,0))),"未")) -> 2 | W37: =IF(A37="","",A37&" "&C37) -> 2134 山下 律 | X37: =IF(A37="","",IF(E37="男",1,IF(E37="女",2,3))) -> 1 | Y37: =IF(OR(M37="〇",M37="○",M37="◯"),1,0) -> 1 | Z37: =IF(OR(N37="〇",N37="○",N37="◯"),1,0) -> 0 | AA37: =IF(OR(O37="〇",O37="○",O37="◯"),1,0) -> 0 | AB37: =IF(OR(P37="〇",P37="○",P37="◯"),1,0) -> 0 | AC37: =IF(A37="","",IF(AA37=1,1,IF(Y37=1,2,IF(Z37=1,3,IF(AB37=1,4,5))))) -> 2 | AD37: =IF(A37="","",IF(K37="",'設定'!$C$37,K37)) -> 83.6 | AE37: =IF(A37="","",AC37*10000000-ROUND(ABS((AD37-'設定'!$C$37)/'設定'!$C$38)*10000,0)) -> 19984234 | AF37: =IF(A37="","",COUNTIF($AE$4:$AE$153,"<"&AE37)+COUNTIFS($AE$4:$AE$153,AE37,$A$4:$A$153,"<"&A37)+1) -> 8 | AG37: =IF(Q37="","",IFERROR(VALUE(LEFT(Q37,FIND(" ",Q37&" ")-1)),IFERROR(INDEX($A$4:$A$153,MATCH(Q37,$C$4:$C$153,0)),""))) | AH37: =IF(R37="","",IFERROR(VALUE(LEFT(R37,FIND(" ",R37&" ")-1)),IFERROR(INDEX($A$4:$A$153,MATCH(R37,$C$4:$C$153,0)),""))) | AI37: =IF(S37="","",IFERROR(VALUE(LEFT(S37,FIND(" ",S37&" ")-1)),IFERROR(INDEX($A$4:$A$153,MATCH(S37,$C$4:$C$153,0)),""))) | AJ37: =IF(OR(A37="",B37=""),"",IF(COUNTIFS($B$4:B37,B37,$A$4:A37,"<>")=1,MAX($AJ$3:AJ36)+1,"")) | AK37: =IF(OR(A37="",NOT(ISNUMBER(L37))),"",L37^2) -> 49 | AL37: =IF(OR(A37="",NOT(ISNUMBER(L37))),0,(L37-INDEX('計算'!$AE$7:$AG$7,X37))/INDEX('計算'!$AE$8:$AG$8,X37)) -> -1.5720495
